Workbook

Sheet Pricing Comps
A1: GLP-1 Telehealth — Proof of Concept for Cash-Pay Async Clinical Model
A2: Company | B2: Monthly Price | C2: What's Included | D2: Clinical Backend | E2: Drug Risk / Regulatory Profile | F2: Notes
A3: MEDVi | B3: $179/month | C3: Physician review, unlimited messaging, 24/7 support | D3: OpenLoop Health | E3: High — compounded semaglutide, not FDA-approved | F3: Sleepgenic's exact reference architecture. 100,000+ patients served
A4: Hims & Hers | B4: $199–299/month | C4: Compounded GLP-1 injections, provider access, app tools | D4: Proprietary | E4: High — compounded injectables | F4: Entered weight loss 2023, scaled rapidly
A5: Ro Body | B5: $99–145/month | C5: Membership + coaching, medication billed separately | D5: Proprietary | E5: High — compounded injectables | F5: Lower membership fee but medication costs extra
A6: Noom Med | B6: $199–279/month | C6: GLP-1 medication included, behavioral coaching, telehealth visits | D6: Proprietary | E6: High — compounded semaglutide | F6: Most comprehensive behavioral layer in the category
A7: Noom Microdose | B7: $149/month | C7: Low-dose compounded GLP-1, telehealth eval, coaching | D7: Proprietary | E7: High — compounded, not FDA-approved | F7: $149 entry price validates Sleepgenic's launch price point exactly
A9: Key insight: Every GLP-1 comp includes a physical compounded drug — cold storage, pharmacy supply chain, FDA gray area. Sleepgenic has none of that. Our cost structure is cleaner at the same or lower price point.
A11: Sleep Treatment Landscape — What Patients Pay Today
A12: Treatment Type | B12: Provider / Product | C12: Price | D12: Requires Specialist | E12: Wait Time | F12: Clinical Depth | G12: Notes
A13: In-person CBT-I therapy | B13: Certified CBT-I therapist | C13: $100–250 per session / $400–2,000 total course | D13: Yes — certified CBT-I credential | E13: 6–12 months waitlist | F13: High | G13: Fewer than 500 certified providers in U.S. Gold standard but inaccessible
A14: Prescription digital therapeutic | B14: Somryst (FDA-cleared app) | C14: High — exact price not publicly listed | D14: Yes — requires prescription | E14: Varies | F14: Medium — app only, no physician | G14: FDA-cleared CBT-I app. No prescribing authority. No medication step-up
A15: Digital CBT-I app | B15: Sleepio (Big Health) | C15: Employer/insurer covered — not D2C cash pay | D15: No | E15: None | F15: Low-Medium | G15: B2B model via CVS Caremark, employers. Not direct to consumer
A16: Primary care visit | B16: General practitioner | C16: $150–300 per visit | D16: No | E16: Days to weeks | F16: Low — sleep not systematically addressed | G16: Most PCPs prescribe Ambien and move on. Not evidence-based
A17: Sleep specialist visit | B17: Board-certified sleep MD | C17: $300–500 per visit out of pocket | D17: Yes | E17: 3–6 months | F17: High | G17: Typically focused on apnea/polysomnography, not insomnia/CBT-I
A18: Sleepgenic | B18: sleepgenic.ai | C18: $149/month ($119 founding) | D18: No — async licensed MD/NP | E18: 24 hours | F18: High — CBT-I protocol + Rx | G18: Only cash-pay async sleep telehealth with prescribing authority and CBT-I protocol
A20: Where Sleepgenic Sits in the Market
A21: Metric | B21: Value
A22: Sleepgenic standard price | B22: $149/month
A23: Sleepgenic founding member price | B23: $119/month
A24: Cheapest GLP-1 telehealth comp (Ro) | B24: $99–145/month (membership only, drug extra)
A25: Most relevant GLP-1 comp (MEDVi) | B25: $179/month (drug included)
A26: In-person CBT-I equivalent monthly cost | B26: $400–1,000+/month (2–4 sessions)
A27: Sleepgenic discount vs. in-person CBT-I | B27: 75–85% cheaper
A28: Sleepgenic vs. MEDVi (same backend) | B28: $30/month less, zero drug cost, cleaner regulatory profile
A29: Patient's next best alternative | B29: 6–12 month waitlist for a specialist
A31: Sleepgenic is priced at or below every meaningful telehealth comp — with a cleaner regulatory profile, no compounded drug exposure, and the only cash-pay async model with CBT-I protocol delivery and prescribing authority in the sleep category.

Sheet Assumptions
A1: SLEEPGENIC — OPERATING MODEL ASSUMPTIONS
A3: TIMING
A4: Launch Month | B4: January
A5: Launch Year | B5: 2026
A7: PRICING
A8: Monthly Subscription Price | B8: 149
A10: CHURN & RETENTION
A11: Monthly Churn Rate (Base Case) | B11: 0.2
A12: Avg Months Subscribed per Patient | B12: =1/B11 -> 5
A13: Avg Revenue per Patient Lifetime | B13: =B12*B8 -> 745
A14: Re-enrollment Rate (% of cumulative churned) | B14: 0.1
A16: PAID ACQUISITION — CHANNEL BREAKDOWN
A17: Paid Search (Google) — CPA | B17: 250
A18: Paid Social (Meta/Instagram) — CPA | B18: 300
A19: Channel Split (% Google Search) | B19: 0.6
A20: Channel Split (% Meta Social) | B20: =1-B19 -> 0.4
A21: Blended Paid CAC (weighted avg) | B21: =B17*B19+B18*B20 -> 270
A23: ORGANIC / SEO ACQUISITION
A24: Organic CPA | B24: 0
A25: Organic % of New Patients — Month 1–3 | B25: 0
A26: Organic % of New Patients — Month 4–6 | B26: 0.05
A27: Organic % of New Patients — Month 7–12 | B27: 0.15
A28: Organic % of New Patients — Month 13–18 | B28: 0.25
A29: Organic % of New Patients — Month 19–24 | B29: 0.35
A31: WORD OF MOUTH / REFERRAL
A32: Referral CPA | B32: 0
A33: Referral % — Month 1–5 | B33: 0
A34: Referral % — Month 6–12 | B34: 0.05
A35: Referral % — Month 13–18 | B35: 0.08
A36: Referral % — Month 18–24 | B36: 0.1
A38: MONTHLY PAID MEDIA BUDGET (BASE CASE)
A39: Starting Monthly Budget (Month 1) | B39: 5000
A40: Monthly Budget Increase — Y1 (M2–M12) | B40: 2000
A41: Monthly Budget Increase — Y2 (M13–M24) | B41: 3000
A43: CLINICAL BACKEND COST
A44: OpenLoop Per-Patient Monthly Fee | B44: 45
A45: Payment Processing Fee (Stripe) | B45: 0.029
A47: FIXED MONTHLY OVERHEAD
A48: Infrastructure (Vercel, Supabase, Cloudflare, Email) | B48: 75
A49: Miscellaneous | B49: 200
...

Sheet Patient Growth
A1: Month | B1: Calendar Month | C1: Monthly Media Budget | D1: New Patients (Paid) | E1: New Patients (Organic) | F1: New Patients (Referral) | G1: Total New Patients | H1: Re-Enrolled Patients | I1: Churned Patients | J1: Net Active Patients | K1: Cumulative Patients Ever | L1: Cumulative Churned | M1: Blended CAC This Month
A2: 1 | B2: =DATE(Assumptions!B5, MATCH(Assumptions!B4, {"January","February","March","April","May","June","July","August","September","October","November","December"}, 0), 1) -> 46023 | C2: =IF(A2<=12, Assumptions!$B$39 + (A2-1)*Assumptions!$B$40, Assumptions!$B$39 + 11*Assumptions!$B$40 + (A2-12)*Assumptions!$B$41) -> 5000 | D2: =MAX(ROUND(C2/Assumptions!$B$21, 0), 1) -> 19 | E2: =ROUND(D2*IF(A2<=3, Assumptions!$B$25, IF(A2<=6, Assumptions!$B$26, IF(A2<=12, Assumptions!$B$27, IF(A2<=18, Assumptions!$B$28, Assumptions!$B$29)))), 0) -> 0 | F2: =ROUND(D2*IF(A2<=5, Assumptions!$B$33, IF(A2<=12, Assumptions!$B$34, IF(A2<=18, Assumptions!$B$35, Assumptions!$B$36))), 0) -> 0 | G2: =D2+E2+F2 -> 19 | H2: 0 | I2: 0 | J2: =G2+H2-I2 -> 19 | K2: =G2 -> 19 | L2: =I2 -> 0 | M2: =IF(G2>0, C2/G2, 0) -> 263.15789
A3: 2 | B3: =EDATE(B2,1) -> 46054 | C3: =IF(A3<=12, Assumptions!$B$39 + (A3-1)*Assumptions!$B$40, Assumptions!$B$39 + 11*Assumptions!$B$40 + (A3-12)*Assumptions!$B$41) -> 7000 | D3: =MAX(ROUND(C3/Assumptions!$B$21, 0), 1) -> 26 | E3: =ROUND(D3*IF(A3<=3, Assumptions!$B$25, IF(A3<=6, Assumptions!$B$26, IF(A3<=12, Assumptions!$B$27, IF(A3<=18, Assumptions!$B$28, Assumptions!$B$29)))), 0) -> 0 | F3: =ROUND(D3*IF(A3<=5, Assumptions!$B$33, IF(A3<=12, Assumptions!$B$34, IF(A3<=18, Assumptions!$B$35, Assumptions!$B$36))), 0) -> 0 | G3: =D3+E3+F3 -> 26 | H3: =IF(A3>=6, ROUND(L2*Assumptions!$B$14,0), 0) -> 0 | I3: =ROUND(J2*Assumptions!$B$11,0) -> 4 | J3: =J2+G3+H3-I3 -> 41 | K3: =K2+G3+H3 -> 45 | L3: =L2+I3 -> 4 | M3: =IF(G3>0, C3/G3, 0) -> 269.23077
A4: 3 | B4: =EDATE(B3,1) -> 46082 | C4: =IF(A4<=12, Assumptions!$B$39 + (A4-1)*Assumptions!$B$40, Assumptions!$B$39 + 11*Assumptions!$B$40 + (A4-12)*Assumptions!$B$41) -> 9000 | D4: =MAX(ROUND(C4/Assumptions!$B$21, 0), 1) -> 33 | E4: =ROUND(D4*IF(A4<=3, Assumptions!$B$25, IF(A4<=6, Assumptions!$B$26, IF(A4<=12, Assumptions!$B$27, IF(A4<=18, Assumptions!$B$28, Assumptions!$B$29)))), 0) -> 0 | F4: =ROUND(D4*IF(A4<=5, Assumptions!$B$33, IF(A4<=12, Assumptions!$B$34, IF(A4<=18, Assumptions!$B$35, Assumptions!$B$36))), 0) -> 0 | G4: =D4+E4+F4 -> 33 | H4: =IF(A4>=6, ROUND(L3*Assumptions!$B$14,0), 0) -> 0 | I4: =ROUND(J3*Assumptions!$B$11,0) -> 8 | J4: =J3+G4+H4-I4 -> 66 | K4: =K3+G4+H4 -> 78 | L4: =L3+I4 -> 12 | M4: =IF(G4>0, C4/G4, 0) -> 272.72727
A5: 4 | B5: =EDATE(B4,1) -> 46113 | C5: =IF(A5<=12, Assumptions!$B$39 + (A5-1)*Assumptions!$B$40, Assumptions!$B$39 + 11*Assumptions!$B$40 + (A5-12)*Assumptions!$B$41) -> 11000 | D5: =MAX(ROUND(C5/Assumptions!$B$21, 0), 1) -> 41 | E5: =ROUND(D5*IF(A5<=3, Assumptions!$B$25, IF(A5<=6, Assumptions!$B$26, IF(A5<=12, Assumptions!$B$27, IF(A5<=18, Assumptions!$B$28, Assumptions!$B$29)))), 0) -> 2 | F5: =ROUND(D5*IF(A5<=5, Assumptions!$B$33, IF(A5<=12, Assumptions!$B$34, IF(A5<=18, Assumptions!$B$35, Assumptions!$B$36))), 0) -> 0 | G5: =D5+E5+F5 -> 43 | H5: =IF(A5>=6, ROUND(L4*Assumptions!$B$14,0), 0) -> 0 | I5: =ROUND(J4*Assumptions!$B$11,0) -> 13 | J5: =J4+G5+H5-I5 -> 96 | K5: =K4+G5+H5 -> 121 | L5: =L4+I5 -> 25 | M5: =IF(G5>0, C5/G5, 0) -> 255.81395
A6: 5 | B6: =EDATE(B5,1) -> 46143 | C6: =IF(A6<=12, Assumptions!$B$39 + (A6-1)*Assumptions!$B$40, Assumptions!$B$39 + 11*Assumptions!$B$40 + (A6-12)*Assumptions!$B$41) -> 13000 | D6: =MAX(ROUND(C6/Assumptions!$B$21, 0), 1) -> 48 | E6: =ROUND(D6*IF(A6<=3, Assumptions!$B$25, IF(A6<=6, Assumptions!$B$26, IF(A6<=12, Assumptions!$B$27, IF(A6<=18, Assumptions!$B$28, Assumptions!$B$29)))), 0) -> 2 | F6: =ROUND(D6*IF(A6<=5, Assumptions!$B$33, IF(A6<=12, Assumptions!$B$34, IF(A6<=18, Assumptions!$B$35, Assumptions!$B$36))), 0) -> 0 | G6: =D6+E6+F6 -> 50 | H6: =IF(A6>=6, ROUND(L5*Assumptions!$B$14,0), 0) -> 0 | I6: =ROUND(J5*Assumptions!$B$11,0) -> 19 | J6: =J5+G6+H6-I6 -> 127 | K6: =K5+G6+H6 -> 171 | L6: =L5+I6 -> 44 | M6: =IF(G6>0, C6/G6, 0) -> 260
A7: 6 | B7: =EDATE(B6,1) -> 46174 | C7: =IF(A7<=12, Assumptions!$B$39 + (A7-1)*Assumptions!$B$40, Assumptions!$B$39 + 11*Assumptions!$B$40 + (A7-12)*Assumptions!$B$41) -> 15000 | D7: =MAX(ROUND(C7/Assumptions!$B$21, 0), 1) -> 56 | E7: =ROUND(D7*IF(A7<=3, Assumptions!$B$25, IF(A7<=6, Assumptions!$B$26, IF(A7<=12, Assumptions!$B$27, IF(A7<=18, Assumptions!$B$28, Assumptions!$B$29)))), 0) -> 3 | F7: =ROUND(D7*IF(A7<=5, Assumptions!$B$33, IF(A7<=12, Assumptions!$B$34, IF(A7<=18, Assumptions!$B$35, Assumptions!$B$36))), 0) -> 3 | G7: =D7+E7+F7 -> 62 | H7: =IF(A7>=6, ROUND(L6*Assumptions!$B$14,0), 0) -> 4 | I7: =ROUND(J6*Assumptions!$B$11,0) -> 25 | J7: =J6+G7+H7-I7 -> 168 | K7: =K6+G7+H7 -> 237 | L7: =L6+I7 -> 69 | M7: =IF(G7>0, C7/G7, 0) -> 241.93548
A8: 7 | B8: =EDATE(B7,1) -> 46204 | C8: =IF(A8<=12, Assumptions!$B$39 + (A8-1)*Assumptions!$B$40, Assumptions!$B$39 + 11*Assumptions!$B$40 + (A8-12)*Assumptions!$B$41) -> 17000 | D8: =MAX(ROUND(C8/Assumptions!$B$21, 0), 1) -> 63 | E8: =ROUND(D8*IF(A8<=3, Assumptions!$B$25, IF(A8<=6, Assumptions!$B$26, IF(A8<=12, Assumptions!$B$27, IF(A8<=18, Assumptions!$B$28, Assumptions!$B$29)))), 0) -> 9 | F8: =ROUND(D8*IF(A8<=5, Assumptions!$B$33, IF(A8<=12, Assumptions!$B$34, IF(A8<=18, Assumptions!$B$35, Assumptions!$B$36))), 0) -> 3 | G8: =D8+E8+F8 -> 75 | H8: =IF(A8>=6, ROUND(L7*Assumptions!$B$14,0), 0) -> 7 | I8: =ROUND(J7*Assumptions!$B$11,0) -> 34 | J8: =J7+G8+H8-I8 -> 216 | K8: =K7+G8+H8 -> 319 | L8: =L7+I8 -> 103 | M8: =IF(G8>0, C8/G8, 0) -> 226.66667
A9: 8 | B9: =EDATE(B8,1) -> 46235 | C9: =IF(A9<=12, Assumptions!$B$39 + (A9-1)*Assumptions!$B$40, Assumptions!$B$39 + 11*Assumptions!$B$40 + (A9-12)*Assumptions!$B$41) -> 19000 | D9: =MAX(ROUND(C9/Assumptions!$B$21, 0), 1) -> 70 | E9: =ROUND(D9*IF(A9<=3, Assumptions!$B$25, IF(A9<=6, Assumptions!$B$26, IF(A9<=12, Assumptions!$B$27, IF(A9<=18, Assumptions!$B$28, Assumptions!$B$29)))), 0) -> 11 | F9: =ROUND(D9*IF(A9<=5, Assumptions!$B$33, IF(A9<=12, Assumptions!$B$34, IF(A9<=18, Assumptions!$B$35, Assumptions!$B$36))), 0) -> 4 | G9: =D9+E9+F9 -> 85 | H9: =IF(A9>=6, ROUND(L8*Assumptions!$B$14,0), 0) -> 10 | I9: =ROUND(J8*Assumptions!$B$11,0) -> 43 | J9: =J8+G9+H9-I9 -> 268 | K9: =K8+G9+H9 -> 414 | L9: =L8+I9 -> 146 | M9: =IF(G9>0, C9/G9, 0) -> 223.52941
A10: 9 | B10: =EDATE(B9,1) -> 46266 | C10: =IF(A10<=12, Assumptions!$B$39 + (A10-1)*Assumptions!$B$40, Assumptions!$B$39 + 11*Assumptions!$B$40 + (A10-12)*Assumptions!$B$41) -> 21000 | D10: =MAX(ROUND(C10/Assumptions!$B$21, 0), 1) -> 78 | E10: =ROUND(D10*IF(A10<=3, Assumptions!$B$25, IF(A10<=6, Assumptions!$B$26, IF(A10<=12, Assumptions!$B$27, IF(A10<=18, Assumptions!$B$28, Assumptions!$B$29)))), 0) -> 12 | F10: =ROUND(D10*IF(A10<=5, Assumptions!$B$33, IF(A10<=12, Assumptions!$B$34, IF(A10<=18, Assumptions!$B$35, Assumptions!$B$36))), 0) -> 4 | G10: =D10+E10+F10 -> 94 | H10: =IF(A10>=6, ROUND(L9*Assumptions!$B$14,0), 0) -> 15 | I10: =ROUND(J9*Assumptions!$B$11,0) -> 54 | J10: =J9+G10+H10-I10 -> 323 | K10: =K9+G10+H10 -> 523 | L10: =L9+I10 -> 200 | M10: =IF(G10>0, C10/G10, 0) -> 223.40426
A11: 10 | B11: =EDATE(B10,1) -> 46296 | C11: =IF(A11<=12, Assumptions!$B$39 + (A11-1)*Assumptions!$B$40, Assumptions!$B$39 + 11*Assumptions!$B$40 + (A11-12)*Assumptions!$B$41) -> 23000 | D11: =MAX(ROUND(C11/Assumptions!$B$21, 0), 1) -> 85 | E11: =ROUND(D11*IF(A11<=3, Assumptions!$B$25, IF(A11<=6, Assumptions!$B$26, IF(A11<=12, Assumptions!$B$27, IF(A11<=18, Assumptions!$B$28, Assumptions!$B$29)))), 0) -> 13 | F11: =ROUND(D11*IF(A11<=5, Assumptions!$B$33, IF(A11<=12, Assumptions!$B$34, IF(A11<=18, Assumptions!$B$35, Assumptions!$B$36))), 0) -> 4 | G11: =D11+E11+F11 -> 102 | H11: =IF(A11>=6, ROUND(L10*Assumptions!$B$14,0), 0) -> 20 | I11: =ROUND(J10*Assumptions!$B$11,0) -> 65 | J11: =J10+G11+H11-I11 -> 380 | K11: =K10+G11+H11 -> 645 | L11: =L10+I11 -> 265 | M11: =IF(G11>0, C11/G11, 0) -> 225.4902
A12: 11 | B12: =EDATE(B11,1) -> 46327 | C12: =IF(A12<=12, Assumptions!$B$39 + (A12-1)*Assumptions!$B$40, Assumptions!$B$39 + 11*Assumptions!$B$40 + (A12-12)*Assumptions!$B$41) -> 25000 | D12: =MAX(ROUND(C12/Assumptions!$B$21, 0), 1) -> 93 | E12: =ROUND(D12*IF(A12<=3, Assumptions!$B$25, IF(A12<=6, Assumptions!$B$26, IF(A12<=12, Assumptions!$B$27, IF(A12<=18, Assumptions!$B$28, Assumptions!$B$29)))), 0) -> 14 | F12: =ROUND(D12*IF(A12<=5, Assumptions!$B$33, IF(A12<=12, Assumptions!$B$34, IF(A12<=18, Assumptions!$B$35, Assumptions!$B$36))), 0) -> 5 | G12: =D12+E12+F12 -> 112 | H12: =IF(A12>=6, ROUND(L11*Assumptions!$B$14,0), 0) -> 27 | I12: =ROUND(J11*Assumptions!$B$11,0) -> 76 | J12: =J11+G12+H12-I12 -> 443 | K12: =K11+G12+H12 -> 784 | L12: =L11+I12 -> 341 | M12: =IF(G12>0, C12/G12, 0) -> 223.21429
A13: 12 | B13: =EDATE(B12,1) -> 46357 | C13: =IF(A13<=12, Assumptions!$B$39 + (A13-1)*Assumptions!$B$40, Assumptions!$B$39 + 11*Assumptions!$B$40 + (A13-12)*Assumptions!$B$41) -> 27000 | D13: =MAX(ROUND(C13/Assumptions!$B$21, 0), 1) -> 100 | E13: =ROUND(D13*IF(A13<=3, Assumptions!$B$25, IF(A13<=6, Assumptions!$B$26, IF(A13<=12, Assumptions!$B$27, IF(A13<=18, Assumptions!$B$28, Assumptions!$B$29)))), 0) -> 15 | F13: =ROUND(D13*IF(A13<=5, Assumptions!$B$33, IF(A13<=12, Assumptions!$B$34, IF(A13<=18, Assumptions!$B$35, Assumptions!$B$36))), 0) -> 5 | G13: =D13+E13+F13 -> 120 | H13: =IF(A13>=6, ROUND(L12*Assumptions!$B$14,0), 0) -> 34 | I13: =ROUND(J12*Assumptions!$B$11,0) -> 89 | J13: =J12+G13+H13-I13 -> 508 | K13: =K12+G13+H13 -> 938 | L13: =L12+I13 -> 430 | M13: =IF(G13>0, C13/G13, 0) -> 225
A14: 13 | B14: =EDATE(B13,1) -> 46388 | C14: =IF(A14<=12, Assumptions!$B$39 + (A14-1)*Assumptions!$B$40, Assumptions!$B$39 + 11*Assumptions!$B$40 + (A14-12)*Assumptions!$B$41) -> 30000 | D14: =MAX(ROUND(C14/Assumptions!$B$21, 0), 1) -> 111 | E14: =ROUND(D14*IF(A14<=3, Assumptions!$B$25, IF(A14<=6, Assumptions!$B$26, IF(A14<=12, Assumptions!$B$27, IF(A14<=18, Assumptions!$B$28, Assumptions!$B$29)))), 0) -> 28 | F14: =ROUND(D14*IF(A14<=5, Assumptions!$B$33, IF(A14<=12, Assumptions!$B$34, IF(A14<=18, Assumptions!$B$35, Assumptions!$B$36))), 0) -> 9 | G14: =D14+E14+F14 -> 148 | H14: =IF(A14>=6, ROUND(L13*Assumptions!$B$14,0), 0) -> 43 | I14: =ROUND(J13*Assumptions!$B$11,0) -> 102 | J14: =J13+G14+H14-I14 -> 597 | K14: =K13+G14+H14 -> 1129 | L14: =L13+I14 -> 532 | M14: =IF(G14>0, C14/G14, 0) -> 202.7027
... A25: 24 | B25: =EDATE(B24,1) -> 46722 | C25: =IF(A25<=12, Assumptions!$B$39 + (A25-1)*Assumptions!$B$40, Assumptions!$B$39 + 11*Assumptions!$B$40 + (A25-12)*Assumptions!$B$41) -> 63000 | D25: =MAX(ROUND(C25/Assumptions!$B$21, 0), 1) -> 233 | E25: =ROUND(D25*IF(A25<=3, Assumptions!$B$25, IF(A25<=6, Assumptions!$B$26, IF(A25<=12, Assumptions!$B$27, IF(A25<=18, Assumptions!$B$28, Assumptions!$B$29)))), 0) -> 82 | F25: =ROUND(D25*IF(A25<=5, Assumptions!$B$33, IF(A25<=12, Assumptions!$B$34, IF(A25<=18, Assumptions!$B$35, Assumptions!$B$36))), 0) -> 23 | G25: =D25+E25+F25 -> 338 | H25: =IF(A25>=6, ROUND(L24*Assumptions!$B$14,0), 0) -> 283 | I25: =ROUND(J24*Assumptions!$B$11,0) -> 409 | J25: =J24+G25+H25-I25 -> 2258 | K25: =K24+G25+H25 -> 5499 | L25: =L24+I25 -> 3241 | M25: =IF(G25>0, C25/G25, 0) -> 186.39053
A27: NOTE | B27: A $5,000/month media budget at $270 blended CAC generates approximately 18 new paid patients in Month 1. This is not a typo. DTC paid acquisition is expensive at launch. The business works because of LTV, not because of cheap clicks.

Sheet Revenue Model
A1: Month | B1: Calendar Month | C1: Active Patients | D1: Gross Revenue | E1: MRR | F1: ARR | G1: Avg Active (Trailing 3mo)
A2: ='Patient Growth'!A2 -> 1 | B2: ='Patient Growth'!B2 -> 46023 | C2: ='Patient Growth'!J2 -> 19 | D2: =C2*Assumptions!$B$8 -> 2831 | E2: =D2 -> 2831 | F2: =E2*12 -> 33972 | G2: =C2 -> 19
A3: ='Patient Growth'!A3 -> 2 | B3: ='Patient Growth'!B3 -> 46054 | C3: ='Patient Growth'!J3 -> 41 | D3: =C3*Assumptions!$B$8 -> 6109 | E3: =D3 -> 6109 | F3: =E3*12 -> 73308 | G3: =IF(A3>=3, ROUND(AVERAGE(C2:C3),0), C3) -> 41
A4: ='Patient Growth'!A4 -> 3 | B4: ='Patient Growth'!B4 -> 46082 | C4: ='Patient Growth'!J4 -> 66 | D4: =C4*Assumptions!$B$8 -> 9834 | E4: =D4 -> 9834 | F4: =E4*12 -> 118008 | G4: =IF(A4>=3, ROUND(AVERAGE(C2:C4),0), C4) -> 42
A5: ='Patient Growth'!A5 -> 4 | B5: ='Patient Growth'!B5 -> 46113 | C5: ='Patient Growth'!J5 -> 96 | D5: =C5*Assumptions!$B$8 -> 14304 | E5: =D5 -> 14304 | F5: =E5*12 -> 171648 | G5: =IF(A5>=3, ROUND(AVERAGE(C3:C5),0), C5) -> 68
A6: ='Patient Growth'!A6 -> 5 | B6: ='Patient Growth'!B6 -> 46143 | C6: ='Patient Growth'!J6 -> 127 | D6: =C6*Assumptions!$B$8 -> 18923 | E6: =D6 -> 18923 | F6: =E6*12 -> 227076 | G6: =IF(A6>=3, ROUND(AVERAGE(C4:C6),0), C6) -> 96
A7: ='Patient Growth'!A7 -> 6 | B7: ='Patient Growth'!B7 -> 46174 | C7: ='Patient Growth'!J7 -> 168 | D7: =C7*Assumptions!$B$8 -> 25032 | E7: =D7 -> 25032 | F7: =E7*12 -> 300384 | G7: =IF(A7>=3, ROUND(AVERAGE(C5:C7),0), C7) -> 130
A8: ='Patient Growth'!A8 -> 7 | B8: ='Patient Growth'!B8 -> 46204 | C8: ='Patient Growth'!J8 -> 216 | D8: =C8*Assumptions!$B$8 -> 32184 | E8: =D8 -> 32184 | F8: =E8*12 -> 386208 | G8: =IF(A8>=3, ROUND(AVERAGE(C6:C8),0), C8) -> 170
A9: ='Patient Growth'!A9 -> 8 | B9: ='Patient Growth'!B9 -> 46235 | C9: ='Patient Growth'!J9 -> 268 | D9: =C9*Assumptions!$B$8 -> 39932 | E9: =D9 -> 39932 | F9: =E9*12 -> 479184 | G9: =IF(A9>=3, ROUND(AVERAGE(C7:C9),0), C9) -> 217
A10: ='Patient Growth'!A10 -> 9 | B10: ='Patient Growth'!B10 -> 46266 | C10: ='Patient Growth'!J10 -> 323 | D10: =C10*Assumptions!$B$8 -> 48127 | E10: =D10 -> 48127 | F10: =E10*12 -> 577524 | G10: =IF(A10>=3, ROUND(AVERAGE(C8:C10),0), C10) -> 269
A11: ='Patient Growth'!A11 -> 10 | B11: ='Patient Growth'!B11 -> 46296 | C11: ='Patient Growth'!J11 -> 380 | D11: =C11*Assumptions!$B$8 -> 56620 | E11: =D11 -> 56620 | F11: =E11*12 -> 679440 | G11: =IF(A11>=3, ROUND(AVERAGE(C9:C11),0), C11) -> 324
A12: ='Patient Growth'!A12 -> 11 | B12: ='Patient Growth'!B12 -> 46327 | C12: ='Patient Growth'!J12 -> 443 | D12: =C12*Assumptions!$B$8 -> 66007 | E12: =D12 -> 66007 | F12: =E12*12 -> 792084 | G12: =IF(A12>=3, ROUND(AVERAGE(C10:C12),0), C12) -> 382
A13: ='Patient Growth'!A13 -> 12 | B13: ='Patient Growth'!B13 -> 46357 | C13: ='Patient Growth'!J13 -> 508 | D13: =C13*Assumptions!$B$8 -> 75692 | E13: =D13 -> 75692 | F13: =E13*12 -> 908304 | G13: =IF(A13>=3, ROUND(AVERAGE(C11:C13),0), C13) -> 444
A14: ='Patient Growth'!A14 -> 13 | B14: ='Patient Growth'!B14 -> 46388 | C14: ='Patient Growth'!J14 -> 597 | D14: =C14*Assumptions!$B$8 -> 88953 | E14: =D14 -> 88953 | F14: =E14*12 -> 1067436 | G14: =IF(A14>=3, ROUND(AVERAGE(C12:C14),0), C14) -> 516
A15: ='Patient Growth'!A15 -> 14 | B15: ='Patient Growth'!B15 -> 46419 | C15: ='Patient Growth'!J15 -> 694 | D15: =C15*Assumptions!$B$8 -> 103406 | E15: =D15 -> 103406 | F15: =E15*12 -> 1240872 | G15: =IF(A15>=3, ROUND(AVERAGE(C13:C15),0), C15) -> 600
... A25: ='Patient Growth'!A25 -> 24 | B25: ='Patient Growth'!B25 -> 46722 | C25: ='Patient Growth'!J25 -> 2258 | D25: =C25*Assumptions!$B$8 -> 336442 | E25: =D25 -> 336442 | F25: =E25*12 -> 4037304 | G25: =IF(A25>=3, ROUND(AVERAGE(C23:C25),0), C25) -> 2051
A27: SUMMARY
A28: Year 1 Total Revenue | B28: =SUM(D2:D13) -> 395595
A29: Year 2 Total Revenue | B29: =SUM(D14:D25) -> 2354200
A30: 24-Month Total Revenue | B30: =SUM(D2:D25) -> 2749795
A31: Month 24 ARR | B31: =F25 -> 4037304
A32: Month 24 Active Patients | B32: =C25 -> 2258

Sheet Cost Model
A1: Month | B1: Calendar Month | C1: OpenLoop Clinical Fee | D1: Payment Processing | E1: Paid Media (Google) | F1: Paid Media (Meta) | G1: Total Paid Media | H1: Implied Paid CAC | I1: Fixed Overhead | J1: Total Monthly Costs
A2: ='Patient Growth'!A2 -> 1 | B2: ='Patient Growth'!B2 -> 46023 | C2: ='Patient Growth'!J2*Assumptions!$B$44 -> 855 | D2: ='Revenue Model'!D2*Assumptions!$B$45 -> 82.099 | E2: ='Patient Growth'!C2*Assumptions!$B$19 -> 3000 | F2: ='Patient Growth'!C2*Assumptions!$B$20 -> 2000 | G2: =E2+F2 -> 5000 | H2: =IF('Patient Growth'!D2>0, G2/'Patient Growth'!D2, 0) -> 263.15789 | I2: =Assumptions!$B$50 -> 275 | J2: =C2+D2+G2+I2 -> 6212.099
A3: ='Patient Growth'!A3 -> 2 | B3: ='Patient Growth'!B3 -> 46054 | C3: ='Patient Growth'!J3*Assumptions!$B$44 -> 1845 | D3: ='Revenue Model'!D3*Assumptions!$B$45 -> 177.161 | E3: ='Patient Growth'!C3*Assumptions!$B$19 -> 4200 | F3: ='Patient Growth'!C3*Assumptions!$B$20 -> 2800 | G3: =E3+F3 -> 7000 | H3: =IF('Patient Growth'!D3>0, G3/'Patient Growth'!D3, 0) -> 269.23077 | I3: =Assumptions!$B$50 -> 275 | J3: =C3+D3+G3+I3 -> 9297.161
A4: ='Patient Growth'!A4 -> 3 | B4: ='Patient Growth'!B4 -> 46082 | C4: ='Patient Growth'!J4*Assumptions!$B$44 -> 2970 | D4: ='Revenue Model'!D4*Assumptions!$B$45 -> 285.186 | E4: ='Patient Growth'!C4*Assumptions!$B$19 -> 5400 | F4: ='Patient Growth'!C4*Assumptions!$B$20 -> 3600 | G4: =E4+F4 -> 9000 | H4: =IF('Patient Growth'!D4>0, G4/'Patient Growth'!D4, 0) -> 272.72727 | I4: =Assumptions!$B$50 -> 275 | J4: =C4+D4+G4+I4 -> 12530.186
A5: ='Patient Growth'!A5 -> 4 | B5: ='Patient Growth'!B5 -> 46113 | C5: ='Patient Growth'!J5*Assumptions!$B$44 -> 4320 | D5: ='Revenue Model'!D5*Assumptions!$B$45 -> 414.816 | E5: ='Patient Growth'!C5*Assumptions!$B$19 -> 6600 | F5: ='Patient Growth'!C5*Assumptions!$B$20 -> 4400 | G5: =E5+F5 -> 11000 | H5: =IF('Patient Growth'!D5>0, G5/'Patient Growth'!D5, 0) -> 268.29268 | I5: =Assumptions!$B$50 -> 275 | J5: =C5+D5+G5+I5 -> 16009.816
A6: ='Patient Growth'!A6 -> 5 | B6: ='Patient Growth'!B6 -> 46143 | C6: ='Patient Growth'!J6*Assumptions!$B$44 -> 5715 | D6: ='Revenue Model'!D6*Assumptions!$B$45 -> 548.767 | E6: ='Patient Growth'!C6*Assumptions!$B$19 -> 7800 | F6: ='Patient Growth'!C6*Assumptions!$B$20 -> 5200 | G6: =E6+F6 -> 13000 | H6: =IF('Patient Growth'!D6>0, G6/'Patient Growth'!D6, 0) -> 270.83333 | I6: =Assumptions!$B$50 -> 275 | J6: =C6+D6+G6+I6 -> 19538.767
A7: ='Patient Growth'!A7 -> 6 | B7: ='Patient Growth'!B7 -> 46174 | C7: ='Patient Growth'!J7*Assumptions!$B$44 -> 7560 | D7: ='Revenue Model'!D7*Assumptions!$B$45 -> 725.928 | E7: ='Patient Growth'!C7*Assumptions!$B$19 -> 9000 | F7: ='Patient Growth'!C7*Assumptions!$B$20 -> 6000 | G7: =E7+F7 -> 15000 | H7: =IF('Patient Growth'!D7>0, G7/'Patient Growth'!D7, 0) -> 267.85714 | I7: =Assumptions!$B$50 -> 275 | J7: =C7+D7+G7+I7 -> 23560.928
A8: ='Patient Growth'!A8 -> 7 | B8: ='Patient Growth'!B8 -> 46204 | C8: ='Patient Growth'!J8*Assumptions!$B$44 -> 9720 | D8: ='Revenue Model'!D8*Assumptions!$B$45 -> 933.336 | E8: ='Patient Growth'!C8*Assumptions!$B$19 -> 10200 | F8: ='Patient Growth'!C8*Assumptions!$B$20 -> 6800 | G8: =E8+F8 -> 17000 | H8: =IF('Patient Growth'!D8>0, G8/'Patient Growth'!D8, 0) -> 269.84127 | I8: =Assumptions!$B$50 -> 275 | J8: =C8+D8+G8+I8 -> 27928.336
A9: ='Patient Growth'!A9 -> 8 | B9: ='Patient Growth'!B9 -> 46235 | C9: ='Patient Growth'!J9*Assumptions!$B$44 -> 12060 | D9: ='Revenue Model'!D9*Assumptions!$B$45 -> 1158.028 | E9: ='Patient Growth'!C9*Assumptions!$B$19 -> 11400 | F9: ='Patient Growth'!C9*Assumptions!$B$20 -> 7600 | G9: =E9+F9 -> 19000 | H9: =IF('Patient Growth'!D9>0, G9/'Patient Growth'!D9, 0) -> 271.42857 | I9: =Assumptions!$B$50 -> 275 | J9: =C9+D9+G9+I9 -> 32493.028
A10: ='Patient Growth'!A10 -> 9 | B10: ='Patient Growth'!B10 -> 46266 | C10: ='Patient Growth'!J10*Assumptions!$B$44 -> 14535 | D10: ='Revenue Model'!D10*Assumptions!$B$45 -> 1395.683 | E10: ='Patient Growth'!C10*Assumptions!$B$19 -> 12600 | F10: ='Patient Growth'!C10*Assumptions!$B$20 -> 8400 | G10: =E10+F10 -> 21000 | H10: =IF('Patient Growth'!D10>0, G10/'Patient Growth'!D10, 0) -> 269.23077 | I10: =Assumptions!$B$50 -> 275 | J10: =C10+D10+G10+I10 -> 37205.683
A11: ='Patient Growth'!A11 -> 10 | B11: ='Patient Growth'!B11 -> 46296 | C11: ='Patient Growth'!J11*Assumptions!$B$44 -> 17100 | D11: ='Revenue Model'!D11*Assumptions!$B$45 -> 1641.98 | E11: ='Patient Growth'!C11*Assumptions!$B$19 -> 13800 | F11: ='Patient Growth'!C11*Assumptions!$B$20 -> 9200 | G11: =E11+F11 -> 23000 | H11: =IF('Patient Growth'!D11>0, G11/'Patient Growth'!D11, 0) -> 270.58824 | I11: =Assumptions!$B$50 -> 275 | J11: =C11+D11+G11+I11 -> 42016.98
A12: ='Patient Growth'!A12 -> 11 | B12: ='Patient Growth'!B12 -> 46327 | C12: ='Patient Growth'!J12*Assumptions!$B$44 -> 19935 | D12: ='Revenue Model'!D12*Assumptions!$B$45 -> 1914.203 | E12: ='Patient Growth'!C12*Assumptions!$B$19 -> 15000 | F12: ='Patient Growth'!C12*Assumptions!$B$20 -> 10000 | G12: =E12+F12 -> 25000 | H12: =IF('Patient Growth'!D12>0, G12/'Patient Growth'!D12, 0) -> 268.8172 | I12: =Assumptions!$B$50 -> 275 | J12: =C12+D12+G12+I12 -> 47124.203
A13: ='Patient Growth'!A13 -> 12 | B13: ='Patient Growth'!B13 -> 46357 | C13: ='Patient Growth'!J13*Assumptions!$B$44 -> 22860 | D13: ='Revenue Model'!D13*Assumptions!$B$45 -> 2195.068 | E13: ='Patient Growth'!C13*Assumptions!$B$19 -> 16200 | F13: ='Patient Growth'!C13*Assumptions!$B$20 -> 10800 | G13: =E13+F13 -> 27000 | H13: =IF('Patient Growth'!D13>0, G13/'Patient Growth'!D13, 0) -> 270 | I13: =Assumptions!$B$50 -> 275 | J13: =C13+D13+G13+I13 -> 52330.068
... A25: ='Patient Growth'!A25 -> 24 | B25: ='Patient Growth'!B25 -> 46722 | C25: ='Patient Growth'!J25*Assumptions!$B$44 -> 101610 | D25: ='Revenue Model'!D25*Assumptions!$B$45 -> 9756.818 | E25: ='Patient Growth'!C25*Assumptions!$B$19 -> 37800 | F25: ='Patient Growth'!C25*Assumptions!$B$20 -> 25200 | G25: =E25+F25 -> 63000 | H25: =IF('Patient Growth'!D25>0, G25/'Patient Growth'!D25, 0) -> 270.38627 | I25: =Assumptions!$B$50 -> 275 | J25: =C25+D25+G25+I25 -> 174641.82
A27: SUMMARY
A28: Year 1 Total Costs | B28: =SUM(J2:J13) -> 326247.26
A29: Year 2 Total Costs | B29: =SUM(J14:J25) -> 1340571.8
A30: 24-Month Total Costs | B30: =SUM(J2:J25) -> 1666819.1
A31: Total Paid Media Spend (24 months) | B31: =SUM(G2:G25) -> 750000
A32: Cost as % of Revenue (M24) | B32: =J25/'Revenue Model'!D25 -> 0.51908447

Sheet Unit Economics
A1: UNIT ECONOMICS DASHBOARD
A3: SECTION 1: PER-PATIENT ECONOMICS | D3: CHURN SENSITIVITY
A4: Monthly Subscription Price | B4: =Assumptions!B8 -> 149 | D4: Monthly Churn | E4: GP per Patient
A5: Monthly Churn Rate | B5: =Assumptions!B11 -> 0.2 | D5: 0.1 | E5: =(1/D5)*149-(45*(1/D5))-(0.029*(1/D5)*149)-Assumptions!$B$21 -> 726.79
A6: Average Months Subscribed | B6: =Assumptions!B53 -> 5 | D6: 0.15 | E6: =(1/D6)*149-(45*(1/D6))-(0.029*(1/D6)*149)-Assumptions!$B$21 -> 394.52667
A7: Lifetime Revenue per Patient | B7: =Assumptions!B54 -> 745 | D7: 0.2 | E7: =(1/D7)*149-(45*(1/D7))-(0.029*(1/D7)*149)-Assumptions!$B$21 -> 228.395
D8: 0.25 | E8: =(1/D8)*149-(45*(1/D8))-(0.029*(1/D8)*149)-Assumptions!$B$21 -> 128.716
A9: OpenLoop Cost per Month | B9: =Assumptions!B44 -> 45 | D9: 0.3 | E9: =(1/D9)*149-(45*(1/D9))-(0.029*(1/D9)*149)-Assumptions!$B$21 -> 62.263333
A10: OpenLoop Cost per Lifetime | B10: =B9*B6 -> 225 | D10: 0.35 | E10: =(1/D10)*149-(45*(1/D10))-(0.029*(1/D10)*149)-Assumptions!$B$21 -> 14.797143
A11: Stripe Processing per Lifetime | B11: =B7*Assumptions!B45 -> 21.605 | D11: 0.37 | E11: =(1/D11)*149-(45*(1/D11))-(0.029*(1/D11)*149)-Assumptions!$B$21 -> -0.5972973 | F11: Breakeven around 37% monthly churn. Anything below that, profit per patient
A12: Blended Paid CAC (worst case, no organic) | B12: =Assumptions!B21 -> 270 | D12: 0.5 | E12: =(1/D12)*149-(45*(1/D12))-(0.029*(1/D12)*149)-Assumptions!$B$21 -> -70.642
A13: Total Cost per Patient Lifetime (at paid CAC) | B13: =B10+B11+B12 -> 516.605
A15: GROSS PROFIT PER PATIENT LIFETIME (PAID CAC) | B15: =B7-B13 -> 228.395
A17: SECTION 2: CAC COMPRESSION OVER TIME
A18: Metric | B18: Value
A19: Blended Paid CAC (Month 1) | B19: ='Patient Growth'!M2 -> 263.15789
A20: Blended CAC Month 12 (with organic) | B20: ='Patient Growth'!M13 -> 225
A21: Blended CAC Month 24 (with organic) | B21: ='Patient Growth'!M25 -> 186.39053
A22: Organic % of Patients by Month 24 | B22: =Assumptions!B29 -> 0.35
A23: Media Budget (Base Case) Month 1 | B23: ='Patient Growth'!C2 -> 5000
A24: Media Budget (Base Case) Month 12 | B24: ='Patient Growth'!C13 -> 27000
A25: Media Budget (Base Case) Month 24 | B25: ='Patient Growth'!C25 -> 63000
A27: SECTION 3: VIABILITY TEST
A28: GP per Patient > $0? | B28: =IF(B15>0,"YES ✔","NO ✘") -> YES ✔
A29: Months to CAC Payback | B29: =Assumptions!B21/(Assumptions!B8-Assumptions!B44-Assumptions!B45*Assumptions!B8) -> 2.7086949
A30: CAC Payback < Avg LTV? | B30: =IF(B29<B6,"YES ✔","NO ✘") -> YES ✔
A31: Lifetime Gross Margin % | B31: =B15/B7 -> 0.30657047
A32: LTV:CAC Ratio (paid) | B32: =B7/B12 -> 2.7592593
A33: WARNING: The P&L may show positive EBITDA even at churn rates above 37% due to revenue from growing active patient base. This is a timing artifact. The Cohort Sustainability Test on the P&L tab is the correct viability measure. A ratio below 1.5x means the business requires perfect execution with no room for CAC increases or churn spikes.
A34: SECTION 4: MEDIA BUDGET REALITY CHECK
A35: Total Media Spend (Year 1) | B35: =SUM('Patient Growth'!C2:C13) -> 192000
A36: Total Media Spend (Year 2) | B36: =SUM('Patient Growth'!C14:C25) -> 558000
A37: Total Media Spend (24 months) | B37: =B35+B36 -> 750000
A39: Total Overhead (24 months) | B39: =Assumptions!B50*24 -> 6600
A40: Max Cash Deficit (from P&L) | B40: ='P&L Summary'!B32 -> -11587.029
A41: Month of First Cumulative Profit | B41: ='P&L Summary'!B33 -> 8
A42: Months 1-3 Cash Required | B42: =-MIN('P&L Summary'!G2:G4) -> 9265.446
A44: 24-Month Cumulative Gross Profit | B44: ='P&L Summary'!G25 -> 1082975.9
A46: ⚠ IMPORTANT: These figures exclude founder salaries, legal, insurance, and non-operational costs. This model shows whether the core unit economics and media-driven growth engine work — not total company burn. Fundraising or personal runway must cover non-operational expenses independently.

Sheet P&L Summary
A1: Month | B1: Calendar Month | C1: Gross Revenue | D1: Total Costs | E1: Gross Profit | F1: Gross Margin % | G1: Cumulative Cash Position | H1: Gross Profit / New Patient | I1: Cohort Sustainability Ratio
A2: ='Patient Growth'!A2 -> 1 | B2: ='Patient Growth'!B2 -> 46023 | C2: ='Revenue Model'!D2 -> 2831 | D2: ='Cost Model'!J2 -> 6212.099 | E2: =C2-D2 -> -3381.099 | F2: =IF(C2=0,0,E2/C2) -> -1.1943126 | G2: =E2 -> -3381.099 | H2: =IF('Patient Growth'!G2=0,0,E2/'Patient Growth'!G2) -> -177.95258 | I2: =IF('Cost Model'!G2=0, 0, ('Patient Growth'!G2*'Unit Economics'!$B$15)/'Cost Model'!G2) -> 0.867901
A3: ='Patient Growth'!A3 -> 2 | B3: ='Patient Growth'!B3 -> 46054 | C3: ='Revenue Model'!D3 -> 6109 | D3: ='Cost Model'!J3 -> 9297.161 | E3: =C3-D3 -> -3188.161 | F3: =IF(C3=0,0,E3/C3) -> -0.52187936 | G3: =G2+E3 -> -6569.26 | H3: =IF('Patient Growth'!G3=0,0,E3/'Patient Growth'!G3) -> -122.62158 | I3: =IF('Cost Model'!G3=0, 0, ('Patient Growth'!G3*'Unit Economics'!$B$15)/'Cost Model'!G3) -> 0.84832429
A4: ='Patient Growth'!A4 -> 3 | B4: ='Patient Growth'!B4 -> 46082 | C4: ='Revenue Model'!D4 -> 9834 | D4: ='Cost Model'!J4 -> 12530.186 | E4: =C4-D4 -> -2696.186 | F4: =IF(C4=0,0,E4/C4) -> -0.27416982 | G4: =G3+E4 -> -9265.446 | H4: =IF('Patient Growth'!G4=0,0,E4/'Patient Growth'!G4) -> -81.702606 | I4: =IF('Cost Model'!G4=0, 0, ('Patient Growth'!G4*'Unit Economics'!$B$15)/'Cost Model'!G4) -> 0.83744833
A5: ='Patient Growth'!A5 -> 4 | B5: ='Patient Growth'!B5 -> 46113 | C5: ='Revenue Model'!D5 -> 14304 | D5: ='Cost Model'!J5 -> 16009.816 | E5: =C5-D5 -> -1705.816 | F5: =IF(C5=0,0,E5/C5) -> -0.11925447 | G5: =G4+E5 -> -10971.262 | H5: =IF('Patient Growth'!E5=0,0,E5/'Patient Growth'!E5) -> -852.908 | I5: =IF('Cost Model'!G5=0, 0, ('Patient Growth'!G5*'Unit Economics'!$B$15)/'Cost Model'!G5) -> 0.89281682
A6: ='Patient Growth'!A6 -> 5 | B6: ='Patient Growth'!B6 -> 46143 | C6: ='Revenue Model'!D6 -> 18923 | D6: ='Cost Model'!J6 -> 19538.767 | E6: =C6-D6 -> -615.767 | F6: =IF(C6=0,0,E6/C6) -> -0.032540665 | G6: =G5+E6 -> -11587.029 | H6: =IF('Patient Growth'!E6=0,0,E6/'Patient Growth'!E6) -> -307.8835 | I6: =IF('Cost Model'!G6=0, 0, ('Patient Growth'!G6*'Unit Economics'!$B$15)/'Cost Model'!G6) -> 0.87844231
A7: ='Patient Growth'!A7 -> 6 | B7: ='Patient Growth'!B7 -> 46174 | C7: ='Revenue Model'!D7 -> 25032 | D7: ='Cost Model'!J7 -> 23560.928 | E7: =C7-D7 -> 1471.072 | F7: =IF(C7=0,0,E7/C7) -> 0.058767657 | G7: =G6+E7 -> -10115.957 | H7: =IF('Patient Growth'!E7=0,0,E7/'Patient Growth'!E7) -> 490.35733 | I7: =IF('Cost Model'!G7=0, 0, ('Patient Growth'!G7*'Unit Economics'!$B$15)/'Cost Model'!G7) -> 0.94403267
A8: ='Patient Growth'!A8 -> 7 | B8: ='Patient Growth'!B8 -> 46204 | C8: ='Revenue Model'!D8 -> 32184 | D8: ='Cost Model'!J8 -> 27928.336 | E8: =C8-D8 -> 4255.664 | F8: =IF(C8=0,0,E8/C8) -> 0.13222918 | G8: =G7+E8 -> -5860.293 | H8: =IF('Patient Growth'!E8=0,0,E8/'Patient Growth'!E8) -> 472.85156 | I8: =IF('Cost Model'!G8=0, 0, ('Patient Growth'!G8*'Unit Economics'!$B$15)/'Cost Model'!G8) -> 1.007625
A9: ='Patient Growth'!A9 -> 8 | B9: ='Patient Growth'!B9 -> 46235 | C9: ='Revenue Model'!D9 -> 39932 | D9: ='Cost Model'!J9 -> 32493.028 | E9: =C9-D9 -> 7438.972 | F9: =IF(C9=0,0,E9/C9) -> 0.18629099 | G9: =G8+E9 -> 1578.679 | H9: =IF('Patient Growth'!E9=0,0,E9/'Patient Growth'!E9) -> 676.27018 | I9: =IF('Cost Model'!G9=0, 0, ('Patient Growth'!G9*'Unit Economics'!$B$15)/'Cost Model'!G9) -> 1.0217671
A10: ='Patient Growth'!A10 -> 9 | B10: ='Patient Growth'!B10 -> 46266 | C10: ='Revenue Model'!D10 -> 48127 | D10: ='Cost Model'!J10 -> 37205.683 | E10: =C10-D10 -> 10921.317 | F10: =IF(C10=0,0,E10/C10) -> 0.22692703 | G10: =G9+E10 -> 12499.996 | H10: =IF('Patient Growth'!E10=0,0,E10/'Patient Growth'!E10) -> 910.10975 | I10: =IF('Cost Model'!G10=0, 0, ('Patient Growth'!G10*'Unit Economics'!$B$15)/'Cost Model'!G10) -> 1.0223395
A11: ='Patient Growth'!A11 -> 10 | B11: ='Patient Growth'!B11 -> 46296 | C11: ='Revenue Model'!D11 -> 56620 | D11: ='Cost Model'!J11 -> 42016.98 | E11: =C11-D11 -> 14603.02 | F11: =IF(C11=0,0,E11/C11) -> 0.25791275 | G11: =G10+E11 -> 27103.016 | H11: =IF('Patient Growth'!E11=0,0,E11/'Patient Growth'!E11) -> 1123.3092 | I11: =IF('Cost Model'!G11=0, 0, ('Patient Growth'!G11*'Unit Economics'!$B$15)/'Cost Model'!G11) -> 1.0128822
A12: ='Patient Growth'!A12 -> 11 | B12: ='Patient Growth'!B12 -> 46327 | C12: ='Revenue Model'!D12 -> 66007 | D12: ='Cost Model'!J12 -> 47124.203 | E12: =C12-D12 -> 18882.797 | F12: =IF(C12=0,0,E12/C12) -> 0.28607264 | G12: =G11+E12 -> 45985.813 | H12: =IF('Patient Growth'!E12=0,0,E12/'Patient Growth'!E12) -> 1348.7712 | I12: =IF('Cost Model'!G12=0, 0, ('Patient Growth'!G12*'Unit Economics'!$B$15)/'Cost Model'!G12) -> 1.0232096
A13: ='Patient Growth'!A13 -> 12 | B13: ='Patient Growth'!B13 -> 46357 | C13: ='Revenue Model'!D13 -> 75692 | D13: ='Cost Model'!J13 -> 52330.068 | E13: =C13-D13 -> 23361.932 | F13: =IF(C13=0,0,E13/C13) -> 0.30864467 | G13: =G12+E13 -> 69347.745 | H13: =IF('Patient Growth'!E13=0,0,E13/'Patient Growth'!E13) -> 1557.4621 | I13: =IF('Cost Model'!G13=0, 0, ('Patient Growth'!G13*'Unit Economics'!$B$15)/'Cost Model'!G13) -> 1.0150889
A14: ='Patient Growth'!A14 -> 13 | B14: ='Patient Growth'!B14 -> 46388 | C14: ='Revenue Model'!D14 -> 88953 | D14: ='Cost Model'!J14 -> 59719.637 | E14: =C14-D14 -> 29233.363 | F14: =IF(C14=0,0,E14/C14) -> 0.3286383 | G14: =G13+E14 -> 98581.108 | H14: =IF('Patient Growth'!E14=0,0,E14/'Patient Growth'!E14) -> 1044.0487 | I14: =IF('Cost Model'!G14=0, 0, ('Patient Growth'!G14*'Unit Economics'!$B$15)/'Cost Model'!G14) -> 1.1267487
A15: ='Patient Growth'!A15 -> 14 | B15: ='Patient Growth'!B15 -> 46419 | C15: ='Revenue Model'!D15 -> 103406 | D15: ='Cost Model'!J15 -> 67503.774 | E15: =C15-D15 -> 35902.226 | F15: =IF(C15=0,0,E15/C15) -> 0.34719674 | G15: =G14+E15 -> 134483.33 | H15: =IF('Patient Growth'!E15=0,0,E15/'Patient Growth'!E15) -> 1158.1363 | I15: =IF('Cost Model'!G15=0, 0, ('Patient Growth'!G15*'Unit Economics'!$B$15)/'Cost Model'!G15) -> 1.1281329
A16: ='Patient Growth'!A16 -> 15 | B16: ='Patient Growth'!B16 -> 46447 | C16: ='Revenue Model'!D16 -> 118753 | D16: ='Cost Model'!J16 -> 75583.837 | E16: =C16-D16 -> 43169.163 | F16: =IF(C16=0,0,E16/C16) -> 0.36352061 | G16: =G15+E16 -> 177652.5 | H16: =IF('Patient Growth'!E16=0,0,E16/'Patient Growth'!E16) -> 1308.1565 | I16: =IF('Cost Model'!G16=0, 0, ('Patient Growth'!G16*'Unit Economics'!$B$15)/'Cost Model'!G16) -> 1.1229421
... A25: ='Patient Growth'!A25 -> 24 | B25: ='Patient Growth'!B25 -> 46722 | C25: ='Revenue Model'!D25 -> 336442 | D25: ='Cost Model'!J25 -> 174641.82 | E25: =C25-D25 -> 161800.18 | F25: =IF(C25=0,0,E25/C25) -> 0.48091553 | G25: =G24+E25 -> 1082975.9 | H25: =IF('Patient Growth'!E25=0,0,E25/'Patient Growth'!E25) -> 1973.173 | I25: =IF('Cost Model'!G25=0, 0, ('Patient Growth'!G25*'Unit Economics'!$B$15)/'Cost Model'!G25) -> 1.2253573
A27: SUMMARY
A28: Year 1 Gross Profit | B28: =SUM(E2:E13) -> 69347.745
A29: Year 2 Gross Profit | B29: =SUM(E14:E25) -> 1013628.2
A30: 24-Month Cumulative Gross Profit | B30: =G25 -> 1082975.9
A31: Avg Gross Margin (Year 2) | B31: =B29/SUM(C14:C25) -> 0.43056163
A32: Max Cash Deficit | B32: =MIN(G2:G25) -> -11587.029
A33: Month of First Cumulative Profit | B33: {=MATCH(TRUE,INDEX(G2:G25>0,0),0)} -> 8
A34: Avg Cohort Sustainability Ratio (Y2) | B34: =AVERAGE(I14:I25) -> 1.1760908
A35: Min Cohort Sustainability Ratio | B35: =MIN(I2:I25) -> 0.83744833

Sheet Scenarios
B1: CONSERVATIVE | O1: BASE CASE | AB1: AGGRESSIVE
B2: Key Assumptions | O2: Key Assumptions | AB2: Key Assumptions
B3: Starting Monthly Budget | C3: 3000 | O3: Starting Monthly Budget | P3: 5000 | AB3: Starting Monthly Budget | AC3: 10000
B4: Y1 Monthly Increase | C4: 1000 | O4: Y1 Monthly Increase | P4: 2000 | AB4: Y1 Monthly Increase | AC4: 3000
B5: Y2 Monthly Increase | C5: 2000 | O5: Y2 Monthly Increase | P5: 3000 | AB5: Y2 Monthly Increase | AC5: 5000
B6: Blended Paid CAC | C6: 300 | O6: Blended Paid CAC | P6: 270 | AB6: Blended Paid CAC | AC6: 220
B7: Monthly Churn Rate | C7: 0.25 | O7: Monthly Churn Rate | P7: 0.2 | AB7: Monthly Churn Rate | AC7: 0.12
B8: Organic % by Month 12 | C8: 0.1 | O8: Organic % by Month 12 | P8: 0.15 | AB8: Organic % by Month 12 | AC8: 0.2
B10: Month | C10: Media Budget | D10: New Paid | E10: Organic+Ref | F10: Total New | G10: Churned | H10: Net Active | I10: Revenue | J10: Total Cost | K10: Gross Profit | L10: Cum Cash | M10: Blended CAC | O10: Month | P10: Media Budget | Q10: New Paid | R10: Organic+Ref | S10: Total New | T10: Churned | U10: Net Active | V10: Revenue | W10: Total Cost | X10: Gross Profit | Y10: Cum Cash | Z10: Blended CAC | AB10: Month | AC10: Media Budget | AD10: New Paid | AE10: Organic+Ref | AF10: Total New | AG10: Churned | AH10: Net Active | AI10: Revenue | AJ10: Total Cost | AK10: Gross Profit | AL10: Cum Cash | AM10: Blended CAC
B11: 1 | C11: =IF(B11<=12, $C$3+(B11-1)*$C$4, $C$3+11*$C$4+(B11-12)*$C$5) -> 3000 | D11: =MAX(ROUND(C11/$C$6, 0), 1) -> 10 | E11: =ROUND(D11*0, 0) -> 0 | F11: =D11+E11 -> 10 | G11: 0 | H11: =F11 -> 10 | I11: =H11*149 -> 1490 | J11: =(H11*45)+(I11*0.029)+C11+275 -> 3768.21 | K11: =I11-J11 -> -2278.21 | L11: =K11 -> -2278.21 | M11: =IF(F11>0, C11/F11, 0) -> 300 | O11: 1 | P11: =IF(O11<=12, $P$3+(O11-1)*$P$4, $P$3+11*$P$4+(O11-12)*$P$5) -> 5000 | Q11: =MAX(ROUND(P11/$P$6, 0), 1) -> 19 | R11: =ROUND(Q11*0, 0) -> 0 | S11: =Q11+R11 -> 19 | T11: 0 | U11: =S11 -> 19 | V11: =U11*149 -> 2831 | W11: =(U11*45)+(V11*0.029)+P11+275 -> 6212.099 | X11: =V11-W11 -> -3381.099 | Y11: =X11 -> -3381.099 | Z11: =IF(S11>0, P11/S11, 0) -> 263.15789 | AB11: 1 | AC11: =IF(AB11<=12, $AC$3+(AB11-1)*$AC$4, $AC$3+11*$AC$4+(AB11-12)*$AC$5) -> 10000 | AD11: =MAX(ROUND(AC11/$AC$6, 0), 1) -> 45 | AE11: =ROUND(AD11*0, 0) -> 0 | AF11: =AD11+AE11 -> 45 | AG11: 0 | AH11: =AF11 -> 45 | AI11: =AH11*149 -> 6705 | AJ11: =(AH11*45)+(AI11*0.029)+AC11+275 -> 12494.445 | AK11: =AI11-AJ11 -> -5789.445 | AL11: =AK11 -> -5789.445 | AM11: =IF(AF11>0, AC11/AF11, 0) -> 222.22222
B12: 2 | C12: =IF(B12<=12, $C$3+(B12-1)*$C$4, $C$3+11*$C$4+(B12-12)*$C$5) -> 4000 | D12: =MAX(ROUND(C12/$C$6, 0), 1) -> 13 | E12: =ROUND(D12*0, 0) -> 0 | F12: =D12+E12 -> 13 | G12: =ROUND(H11*$C$7, 0) -> 3 | H12: =H11+F12-G12 -> 20 | I12: =H12*149 -> 2980 | J12: =(H12*45)+(I12*0.029)+C12+275 -> 5261.42 | K12: =I12-J12 -> -2281.42 | L12: =L11+K12 -> -4559.63 | M12: =IF(F12>0, C12/F12, 0) -> 307.69231 | O12: 2 | P12: =IF(O12<=12, $P$3+(O12-1)*$P$4, $P$3+11*$P$4+(O12-12)*$P$5) -> 7000 | Q12: =MAX(ROUND(P12/$P$6, 0), 1) -> 26 | R12: =ROUND(Q12*0, 0) -> 0 | S12: =Q12+R12 -> 26 | T12: =ROUND(U11*$P$7, 0) -> 4 | U12: =U11+S12-T12 -> 41 | V12: =U12*149 -> 6109 | W12: =(U12*45)+(V12*0.029)+P12+275 -> 9297.161 | X12: =V12-W12 -> -3188.161 | Y12: =Y11+X12 -> -6569.26 | Z12: =IF(S12>0, P12/S12, 0) -> 269.23077 | AB12: 2 | AC12: =IF(AB12<=12, $AC$3+(AB12-1)*$AC$4, $AC$3+11*$AC$4+(AB12-12)*$AC$5) -> 13000 | AD12: =MAX(ROUND(AC12/$AC$6, 0), 1) -> 59 | AE12: =ROUND(AD12*0, 0) -> 0 | AF12: =AD12+AE12 -> 59 | AG12: =ROUND(AH11*$AC$7, 0) -> 5 | AH12: =AH11+AF12-AG12 -> 99 | AI12: =AH12*149 -> 14751 | AJ12: =(AH12*45)+(AI12*0.029)+AC12+275 -> 18157.779 | AK12: =AI12-AJ12 -> -3406.779 | AL12: =AL11+AK12 -> -9196.224 | AM12: =IF(AF12>0, AC12/AF12, 0) -> 220.33898
B13: 3 | C13: =IF(B13<=12, $C$3+(B13-1)*$C$4, $C$3+11*$C$4+(B13-12)*$C$5) -> 5000 | D13: =MAX(ROUND(C13/$C$6, 0), 1) -> 17 | E13: =ROUND(D13*0, 0) -> 0 | F13: =D13+E13 -> 17 | G13: =ROUND(H12*$C$7, 0) -> 5 | H13: =H12+F13-G13 -> 32 | I13: =H13*149 -> 4768 | J13: =(H13*45)+(I13*0.029)+C13+275 -> 6853.272 | K13: =I13-J13 -> -2085.272 | L13: =L12+K13 -> -6644.902 | M13: =IF(F13>0, C13/F13, 0) -> 294.11765 | O13: 3 | P13: =IF(O13<=12, $P$3+(O13-1)*$P$4, $P$3+11*$P$4+(O13-12)*$P$5) -> 9000 | Q13: =MAX(ROUND(P13/$P$6, 0), 1) -> 33 | R13: =ROUND(Q13*0, 0) -> 0 | S13: =Q13+R13 -> 33 | T13: =ROUND(U12*$P$7, 0) -> 8 | U13: =U12+S13-T13 -> 66 | V13: =U13*149 -> 9834 | W13: =(U13*45)+(V13*0.029)+P13+275 -> 12530.186 | X13: =V13-W13 -> -2696.186 | Y13: =Y12+X13 -> -9265.446 | Z13: =IF(S13>0, P13/S13, 0) -> 272.72727 | AB13: 3 | AC13: =IF(AB13<=12, $AC$3+(AB13-1)*$AC$4, $AC$3+11*$AC$4+(AB13-12)*$AC$5) -> 16000 | AD13: =MAX(ROUND(AC13/$AC$6, 0), 1) -> 73 | AE13: =ROUND(AD13*0, 0) -> 0 | AF13: =AD13+AE13 -> 73 | AG13: =ROUND(AH12*$AC$7, 0) -> 12 | AH13: =AH12+AF13-AG13 -> 160 | AI13: =AH13*149 -> 23840 | AJ13: =(AH13*45)+(AI13*0.029)+AC13+275 -> 24166.36 | AK13: =AI13-AJ13 -> -326.36 | AL13: =AL12+AK13 -> -9522.584 | AM13: =IF(AF13>0, AC13/AF13, 0) -> 219.17808
B14: 4 | C14: =IF(B14<=12, $C$3+(B14-1)*$C$4, $C$3+11*$C$4+(B14-12)*$C$5) -> 6000 | D14: =MAX(ROUND(C14/$C$6, 0), 1) -> 20 | E14: =ROUND(D14*0.02, 0) -> 0 | F14: =D14+E14 -> 20 | G14: =ROUND(H13*$C$7, 0) -> 8 | H14: =H13+F14-G14 -> 44 | I14: =H14*149 -> 6556 | J14: =(H14*45)+(I14*0.029)+C14+275 -> 8445.124 | K14: =I14-J14 -> -1889.124 | L14: =L13+K14 -> -8534.026 | M14: =IF(F14>0, C14/F14, 0) -> 300 | O14: 4 | P14: =IF(O14<=12, $P$3+(O14-1)*$P$4, $P$3+11*$P$4+(O14-12)*$P$5) -> 11000 | Q14: =MAX(ROUND(P14/$P$6, 0), 1) -> 41 | R14: =ROUND(Q14*0.05, 0) -> 2 | S14: =Q14+R14 -> 43 | T14: =ROUND(U13*$P$7, 0) -> 13 | U14: =U13+S14-T14 -> 96 | V14: =U14*149 -> 14304 | W14: =(U14*45)+(V14*0.029)+P14+275 -> 16009.816 | X14: =V14-W14 -> -1705.816 | Y14: =Y13+X14 -> -10971.262 | Z14: =IF(S14>0, P14/S14, 0) -> 255.81395 | AB14: 4 | AC14: =IF(AB14<=12, $AC$3+(AB14-1)*$AC$4, $AC$3+11*$AC$4+(AB14-12)*$AC$5) -> 19000 | AD14: =MAX(ROUND(AC14/$AC$6, 0), 1) -> 86 | AE14: =ROUND(AD14*0.08, 0) -> 7 | AF14: =AD14+AE14 -> 93 | AG14: =ROUND(AH13*$AC$7, 0) -> 19 | AH14: =AH13+AF14-AG14 -> 234 | AI14: =AH14*149 -> 34866 | AJ14: =(AH14*45)+(AI14*0.029)+AC14+275 -> 30816.114 | AK14: =AI14-AJ14 -> 4049.886 | AL14: =AL13+AK14 -> -5472.698 | AM14: =IF(AF14>0, AC14/AF14, 0) -> 204.30108
B15: 5 | C15: =IF(B15<=12, $C$3+(B15-1)*$C$4, $C$3+11*$C$4+(B15-12)*$C$5) -> 7000 | D15: =MAX(ROUND(C15/$C$6, 0), 1) -> 23 | E15: =ROUND(D15*0.02, 0) -> 0 | F15: =D15+E15 -> 23 | G15: =ROUND(H14*$C$7, 0) -> 11 | H15: =H14+F15-G15 -> 56 | I15: =H15*149 -> 8344 | J15: =(H15*45)+(I15*0.029)+C15+275 -> 10036.976 | K15: =I15-J15 -> -1692.976 | L15: =L14+K15 -> -10227.002 | M15: =IF(F15>0, C15/F15, 0) -> 304.34783 | O15: 5 | P15: =IF(O15<=12, $P$3+(O15-1)*$P$4, $P$3+11*$P$4+(O15-12)*$P$5) -> 13000 | Q15: =MAX(ROUND(P15/$P$6, 0), 1) -> 48 | R15: =ROUND(Q15*0.05, 0) -> 2 | S15: =Q15+R15 -> 50 | T15: =ROUND(U14*$P$7, 0) -> 19 | U15: =U14+S15-T15 -> 127 | V15: =U15*149 -> 18923 | W15: =(U15*45)+(V15*0.029)+P15+275 -> 19538.767 | X15: =V15-W15 -> -615.767 | Y15: =Y14+X15 -> -11587.029 | Z15: =IF(S15>0, P15/S15, 0) -> 260 | AB15: 5 | AC15: =IF(AB15<=12, $AC$3+(AB15-1)*$AC$4, $AC$3+11*$AC$4+(AB15-12)*$AC$5) -> 22000 | AD15: =MAX(ROUND(AC15/$AC$6, 0), 1) -> 100 | AE15: =ROUND(AD15*0.08, 0) -> 8 | AF15: =AD15+AE15 -> 108 | AG15: =ROUND(AH14*$AC$7, 0) -> 28 | AH15: =AH14+AF15-AG15 -> 314 | AI15: =AH15*149 -> 46786 | AJ15: =(AH15*45)+(AI15*0.029)+AC15+275 -> 37761.794 | AK15: =AI15-AJ15 -> 9024.206 | AL15: =AL14+AK15 -> 3551.508 | AM15: =IF(AF15>0, AC15/AF15, 0) -> 203.7037
B16: 6 | C16: =IF(B16<=12, $C$3+(B16-1)*$C$4, $C$3+11*$C$4+(B16-12)*$C$5) -> 8000 | D16: =MAX(ROUND(C16/$C$6, 0), 1) -> 27 | E16: =ROUND(D16*0.05, 0) -> 1 | F16: =D16+E16 -> 28 | G16: =ROUND(H15*$C$7, 0) -> 14 | H16: =H15+F16-G16 -> 70 | I16: =H16*149 -> 10430 | J16: =(H16*45)+(I16*0.029)+C16+275 -> 11727.47 | K16: =I16-J16 -> -1297.47 | L16: =L15+K16 -> -11524.472 | M16: =IF(F16>0, C16/F16, 0) -> 285.71429 | O16: 6 | P16: =IF(O16<=12, $P$3+(O16-1)*$P$4, $P$3+11*$P$4+(O16-12)*$P$5) -> 15000 | Q16: =MAX(ROUND(P16/$P$6, 0), 1) -> 56 | R16: =ROUND(Q16*0.1, 0) -> 6 | S16: =Q16+R16 -> 62 | T16: =ROUND(U15*$P$7, 0) -> 25 | U16: =U15+S16-T16 -> 164 | V16: =U16*149 -> 24436 | W16: =(U16*45)+(V16*0.029)+P16+275 -> 23363.644 | X16: =V16-W16 -> 1072.356 | Y16: =Y15+X16 -> -10514.673 | Z16: =IF(S16>0, P16/S16, 0) -> 241.93548 | AB16: 6 | AC16: =IF(AB16<=12, $AC$3+(AB16-1)*$AC$4, $AC$3+11*$AC$4+(AB16-12)*$AC$5) -> 25000 | AD16: =MAX(ROUND(AC16/$AC$6, 0), 1) -> 114 | AE16: =ROUND(AD16*0.15, 0) -> 17 | AF16: =AD16+AE16 -> 131 | AG16: =ROUND(AH15*$AC$7, 0) -> 38 | AH16: =AH15+AF16-AG16 -> 407 | AI16: =AH16*149 -> 60643 | AJ16: =(AH16*45)+(AI16*0.029)+AC16+275 -> 45348.647 | AK16: =AI16-AJ16 -> 15294.353 | AL16: =AL15+AK16 -> 18845.861 | AM16: =IF(AF16>0, AC16/AF16, 0) -> 190.83969
B17: 7 | C17: =IF(B17<=12, $C$3+(B17-1)*$C$4, $C$3+11*$C$4+(B17-12)*$C$5) -> 9000 | D17: =MAX(ROUND(C17/$C$6, 0), 1) -> 30 | E17: =ROUND(D17*0.13, 0) -> 4 | F17: =D17+E17 -> 34 | G17: =ROUND(H16*$C$7, 0) -> 18 | H17: =H16+F17-G17 -> 86 | I17: =H17*149 -> 12814 | J17: =(H17*45)+(I17*0.029)+C17+275 -> 13516.606 | K17: =I17-J17 -> -702.606 | L17: =L16+K17 -> -12227.078 | M17: =IF(F17>0, C17/F17, 0) -> 264.70588 | O17: 7 | P17: =IF(O17<=12, $P$3+(O17-1)*$P$4, $P$3+11*$P$4+(O17-12)*$P$5) -> 17000 | Q17: =MAX(ROUND(P17/$P$6, 0), 1) -> 63 | R17: =ROUND(Q17*0.2, 0) -> 13 | S17: =Q17+R17 -> 76 | T17: =ROUND(U16*$P$7, 0) -> 33 | U17: =U16+S17-T17 -> 207 | V17: =U17*149 -> 30843 | W17: =(U17*45)+(V17*0.029)+P17+275 -> 27484.447 | X17: =V17-W17 -> 3358.553 | Y17: =Y16+X17 -> -7156.12 | Z17: =IF(S17>0, P17/S17, 0) -> 223.68421 | AB17: 7 | AC17: =IF(AB17<=12, $AC$3+(AB17-1)*$AC$4, $AC$3+11*$AC$4+(AB17-12)*$AC$5) -> 28000 | AD17: =MAX(ROUND(AC17/$AC$6, 0), 1) -> 127 | AE17: =ROUND(AD17*0.27, 0) -> 34 | AF17: =AD17+AE17 -> 161 | AG17: =ROUND(AH16*$AC$7, 0) -> 49 | AH17: =AH16+AF17-AG17 -> 519 | AI17: =AH17*149 -> 77331 | AJ17: =(AH17*45)+(AI17*0.029)+AC17+275 -> 53872.599 | AK17: =AI17-AJ17 -> 23458.401 | AL17: =AL16+AK17 -> 42304.262 | AM17: =IF(AF17>0, AC17/AF17, 0) -> 173.91304
B18: 8 | C18: =IF(B18<=12, $C$3+(B18-1)*$C$4, $C$3+11*$C$4+(B18-12)*$C$5) -> 10000 | D18: =MAX(ROUND(C18/$C$6, 0), 1) -> 33 | E18: =ROUND(D18*0.13, 0) -> 4 | F18: =D18+E18 -> 37 | G18: =ROUND(H17*$C$7, 0) -> 22 | H18: =H17+F18-G18 -> 101 | I18: =H18*149 -> 15049 | J18: =(H18*45)+(I18*0.029)+C18+275 -> 15256.421 | K18: =I18-J18 -> -207.421 | L18: =L17+K18 -> -12434.499 | M18: =IF(F18>0, C18/F18, 0) -> 270.27027 | O18: 8 | P18: =IF(O18<=12, $P$3+(O18-1)*$P$4, $P$3+11*$P$4+(O18-12)*$P$5) -> 19000 | Q18: =MAX(ROUND(P18/$P$6, 0), 1) -> 70 | R18: =ROUND(Q18*0.2, 0) -> 14 | S18: =Q18+R18 -> 84 | T18: =ROUND(U17*$P$7, 0) -> 41 | U18: =U17+S18-T18 -> 250 | V18: =U18*149 -> 37250 | W18: =(U18*45)+(V18*0.029)+P18+275 -> 31605.25 | X18: =V18-W18 -> 5644.75 | Y18: =Y17+X18 -> -1511.37 | Z18: =IF(S18>0, P18/S18, 0) -> 226.19048 | AB18: 8 | AC18: =IF(AB18<=12, $AC$3+(AB18-1)*$AC$4, $AC$3+11*$AC$4+(AB18-12)*$AC$5) -> 31000 | AD18: =MAX(ROUND(AC18/$AC$6, 0), 1) -> 141 | AE18: =ROUND(AD18*0.27, 0) -> 38 | AF18: =AD18+AE18 -> 179 | AG18: =ROUND(AH17*$AC$7, 0) -> 62 | AH18: =AH17+AF18-AG18 -> 636 | AI18: =AH18*149 -> 94764 | AJ18: =(AH18*45)+(AI18*0.029)+AC18+275 -> 62643.156 | AK18: =AI18-AJ18 -> 32120.844 | AL18: =AL17+AK18 -> 74425.106 | AM18: =IF(AF18>0, AC18/AF18, 0) -> 173.18436
B19: 9 | C19: =IF(B19<=12, $C$3+(B19-1)*$C$4, $C$3+11*$C$4+(B19-12)*$C$5) -> 11000 | D19: =MAX(ROUND(C19/$C$6, 0), 1) -> 37 | E19: =ROUND(D19*0.13, 0) -> 5 | F19: =D19+E19 -> 42 | G19: =ROUND(H18*$C$7, 0) -> 25 | H19: =H18+F19-G19 -> 118 | I19: =H19*149 -> 17582 | J19: =(H19*45)+(I19*0.029)+C19+275 -> 17094.878 | K19: =I19-J19 -> 487.122 | L19: =L18+K19 -> -11947.377 | M19: =IF(F19>0, C19/F19, 0) -> 261.90476 | O19: 9 | P19: =IF(O19<=12, $P$3+(O19-1)*$P$4, $P$3+11*$P$4+(O19-12)*$P$5) -> 21000 | Q19: =MAX(ROUND(P19/$P$6, 0), 1) -> 78 | R19: =ROUND(Q19*0.2, 0) -> 16 | S19: =Q19+R19 -> 94 | T19: =ROUND(U18*$P$7, 0) -> 50 | U19: =U18+S19-T19 -> 294 | V19: =U19*149 -> 43806 | W19: =(U19*45)+(V19*0.029)+P19+275 -> 35775.374 | X19: =V19-W19 -> 8030.626 | Y19: =Y18+X19 -> 6519.256 | Z19: =IF(S19>0, P19/S19, 0) -> 223.40426 | AB19: 9 | AC19: =IF(AB19<=12, $AC$3+(AB19-1)*$AC$4, $AC$3+11*$AC$4+(AB19-12)*$AC$5) -> 34000 | AD19: =MAX(ROUND(AC19/$AC$6, 0), 1) -> 155 | AE19: =ROUND(AD19*0.27, 0) -> 42 | AF19: =AD19+AE19 -> 197 | AG19: =ROUND(AH18*$AC$7, 0) -> 76 | AH19: =AH18+AF19-AG19 -> 757 | AI19: =AH19*149 -> 112793 | AJ19: =(AH19*45)+(AI19*0.029)+AC19+275 -> 71610.997 | AK19: =AI19-AJ19 -> 41182.003 | AL19: =AL18+AK19 -> 115607.11 | AM19: =IF(AF19>0, AC19/AF19, 0) -> 172.58883
B20: 10 | C20: =IF(B20<=12, $C$3+(B20-1)*$C$4, $C$3+11*$C$4+(B20-12)*$C$5) -> 12000 | D20: =MAX(ROUND(C20/$C$6, 0), 1) -> 40 | E20: =ROUND(D20*0.13, 0) -> 5 | F20: =D20+E20 -> 45 | G20: =ROUND(H19*$C$7, 0) -> 30 | H20: =H19+F20-G20 -> 133 | I20: =H20*149 -> 19817 | J20: =(H20*45)+(I20*0.029)+C20+275 -> 18834.693 | K20: =I20-J20 -> 982.307 | L20: =L19+K20 -> -10965.07 | M20: =IF(F20>0, C20/F20, 0) -> 266.66667 | O20: 10 | P20: =IF(O20<=12, $P$3+(O20-1)*$P$4, $P$3+11*$P$4+(O20-12)*$P$5) -> 23000 | Q20: =MAX(ROUND(P20/$P$6, 0), 1) -> 85 | R20: =ROUND(Q20*0.2, 0) -> 17 | S20: =Q20+R20 -> 102 | T20: =ROUND(U19*$P$7, 0) -> 59 | U20: =U19+S20-T20 -> 337 | V20: =U20*149 -> 50213 | W20: =(U20*45)+(V20*0.029)+P20+275 -> 39896.177 | X20: =V20-W20 -> 10316.823 | Y20: =Y19+X20 -> 16836.079 | Z20: =IF(S20>0, P20/S20, 0) -> 225.4902 | AB20: 10 | AC20: =IF(AB20<=12, $AC$3+(AB20-1)*$AC$4, $AC$3+11*$AC$4+(AB20-12)*$AC$5) -> 37000 | AD20: =MAX(ROUND(AC20/$AC$6, 0), 1) -> 168 | AE20: =ROUND(AD20*0.27, 0) -> 45 | AF20: =AD20+AE20 -> 213 | AG20: =ROUND(AH19*$AC$7, 0) -> 91 | AH20: =AH19+AF20-AG20 -> 879 | AI20: =AH20*149 -> 130971 | AJ20: =(AH20*45)+(AI20*0.029)+AC20+275 -> 80628.159 | AK20: =AI20-AJ20 -> 50342.841 | AL20: =AL19+AK20 -> 165949.95 | AM20: =IF(AF20>0, AC20/AF20, 0) -> 173.70892
B21: 11 | C21: =IF(B21<=12, $C$3+(B21-1)*$C$4, $C$3+11*$C$4+(B21-12)*$C$5) -> 13000 | D21: =MAX(ROUND(C21/$C$6, 0), 1) -> 43 | E21: =ROUND(D21*0.13, 0) -> 6 | F21: =D21+E21 -> 49 | G21: =ROUND(H20*$C$7, 0) -> 33 | H21: =H20+F21-G21 -> 149 | I21: =H21*149 -> 22201 | J21: =(H21*45)+(I21*0.029)+C21+275 -> 20623.829 | K21: =I21-J21 -> 1577.171 | L21: =L20+K21 -> -9387.899 | M21: =IF(F21>0, C21/F21, 0) -> 265.30612 | O21: 11 | P21: =IF(O21<=12, $P$3+(O21-1)*$P$4, $P$3+11*$P$4+(O21-12)*$P$5) -> 25000 | Q21: =MAX(ROUND(P21/$P$6, 0), 1) -> 93 | R21: =ROUND(Q21*0.2, 0) -> 19 | S21: =Q21+R21 -> 112 | T21: =ROUND(U20*$P$7, 0) -> 67 | U21: =U20+S21-T21 -> 382 | V21: =U21*149 -> 56918 | W21: =(U21*45)+(V21*0.029)+P21+275 -> 44115.622 | X21: =V21-W21 -> 12802.378 | Y21: =Y20+X21 -> 29638.457 | Z21: =IF(S21>0, P21/S21, 0) -> 223.21429 | AB21: 11 | AC21: =IF(AB21<=12, $AC$3+(AB21-1)*$AC$4, $AC$3+11*$AC$4+(AB21-12)*$AC$5) -> 40000 | AD21: =MAX(ROUND(AC21/$AC$6, 0), 1) -> 182 | AE21: =ROUND(AD21*0.27, 0) -> 49 | AF21: =AD21+AE21 -> 231 | AG21: =ROUND(AH20*$AC$7, 0) -> 105 | AH21: =AH20+AF21-AG21 -> 1005 | AI21: =AH21*149 -> 149745 | AJ21: =(AH21*45)+(AI21*0.029)+AC21+275 -> 89842.605 | AK21: =AI21-AJ21 -> 59902.395 | AL21: =AL20+AK21 -> 225852.35 | AM21: =IF(AF21>0, AC21/AF21, 0) -> 173.16017
B22: 12 | C22: =IF(B22<=12, $C$3+(B22-1)*$C$4, $C$3+11*$C$4+(B22-12)*$C$5) -> 14000 | D22: =MAX(ROUND(C22/$C$6, 0), 1) -> 47 | E22: =ROUND(D22*0.13, 0) -> 6 | F22: =D22+E22 -> 53 | G22: =ROUND(H21*$C$7, 0) -> 37 | H22: =H21+F22-G22 -> 165 | I22: =H22*149 -> 24585 | J22: =(H22*45)+(I22*0.029)+C22+275 -> 22412.965 | K22: =I22-J22 -> 2172.035 | L22: =L21+K22 -> -7215.864 | M22: =IF(F22>0, C22/F22, 0) -> 264.15094 | O22: 12 | P22: =IF(O22<=12, $P$3+(O22-1)*$P$4, $P$3+11*$P$4+(O22-12)*$P$5) -> 27000 | Q22: =MAX(ROUND(P22/$P$6, 0), 1) -> 100 | R22: =ROUND(Q22*0.2, 0) -> 20 | S22: =Q22+R22 -> 120 | T22: =ROUND(U21*$P$7, 0) -> 76 | U22: =U21+S22-T22 -> 426 | V22: =U22*149 -> 63474 | W22: =(U22*45)+(V22*0.029)+P22+275 -> 48285.746 | X22: =V22-W22 -> 15188.254 | Y22: =Y21+X22 -> 44826.711 | Z22: =IF(S22>0, P22/S22, 0) -> 225 | AB22: 12 | AC22: =IF(AB22<=12, $AC$3+(AB22-1)*$AC$4, $AC$3+11*$AC$4+(AB22-12)*$AC$5) -> 43000 | AD22: =MAX(ROUND(AC22/$AC$6, 0), 1) -> 195 | AE22: =ROUND(AD22*0.27, 0) -> 53 | AF22: =AD22+AE22 -> 248 | AG22: =ROUND(AH21*$AC$7, 0) -> 121 | AH22: =AH21+AF22-AG22 -> 1132 | AI22: =AH22*149 -> 168668 | AJ22: =(AH22*45)+(AI22*0.029)+AC22+275 -> 99106.372 | AK22: =AI22-AJ22 -> 69561.628 | AL22: =AL21+AK22 -> 295413.97 | AM22: =IF(AF22>0, AC22/AF22, 0) -> 173.3871
B23: 13 | C23: =IF(B23<=12, $C$3+(B23-1)*$C$4, $C$3+11*$C$4+(B23-12)*$C$5) -> 16000 | D23: =MAX(ROUND(C23/$C$6, 0), 1) -> 53 | E23: =ROUND(D23*0.229999999999999, 0) -> 12 | F23: =D23+E23 -> 65 | G23: =ROUND(H22*$C$7, 0) -> 41 | H23: =H22+F23-G23 -> 189 | I23: =H23*149 -> 28161 | J23: =(H23*45)+(I23*0.029)+C23+275 -> 25596.669 | K23: =I23-J23 -> 2564.331 | L23: =L22+K23 -> -4651.533 | M23: =IF(F23>0, C23/F23, 0) -> 246.15385 | O23: 13 | P23: =IF(O23<=12, $P$3+(O23-1)*$P$4, $P$3+11*$P$4+(O23-12)*$P$5) -> 30000 | Q23: =MAX(ROUND(P23/$P$6, 0), 1) -> 111 | R23: =ROUND(Q23*0.33, 0) -> 37 | S23: =Q23+R23 -> 148 | T23: =ROUND(U22*$P$7, 0) -> 85 | U23: =U22+S23-T23 -> 489 | V23: =U23*149 -> 72861 | W23: =(U23*45)+(V23*0.029)+P23+275 -> 54392.969 | X23: =V23-W23 -> 18468.031 | Y23: =Y22+X23 -> 63294.742 | Z23: =IF(S23>0, P23/S23, 0) -> 202.7027 | AB23: 13 | AC23: =IF(AB23<=12, $AC$3+(AB23-1)*$AC$4, $AC$3+11*$AC$4+(AB23-12)*$AC$5) -> 48000 | AD23: =MAX(ROUND(AC23/$AC$6, 0), 1) -> 218 | AE23: =ROUND(AD23*0.4, 0) -> 87 | AF23: =AD23+AE23 -> 305 | AG23: =ROUND(AH22*$AC$7, 0) -> 136 | AH23: =AH22+AF23-AG23 -> 1301 | AI23: =AH23*149 -> 193849 | AJ23: =(AH23*45)+(AI23*0.029)+AC23+275 -> 112441.62 | AK23: =AI23-AJ23 -> 81407.379 | AL23: =AL22+AK23 -> 376821.35 | AM23: =IF(AF23>0, AC23/AF23, 0) -> 157.37705
B24: 14 | C24: =IF(B24<=12, $C$3+(B24-1)*$C$4, $C$3+11*$C$4+(B24-12)*$C$5) -> 18000 | D24: =MAX(ROUND(C24/$C$6, 0), 1) -> 60 | E24: =ROUND(D24*0.229999999999999, 0) -> 14 | F24: =D24+E24 -> 74 | G24: =ROUND(H23*$C$7, 0) -> 47 | H24: =H23+F24-G24 -> 216 | I24: =H24*149 -> 32184 | J24: =(H24*45)+(I24*0.029)+C24+275 -> 28928.336 | K24: =I24-J24 -> 3255.664 | L24: =L23+K24 -> -1395.869 | M24: =IF(F24>0, C24/F24, 0) -> 243.24324 | O24: 14 | P24: =IF(O24<=12, $P$3+(O24-1)*$P$4, $P$3+11*$P$4+(O24-12)*$P$5) -> 33000 | Q24: =MAX(ROUND(P24/$P$6, 0), 1) -> 122 | R24: =ROUND(Q24*0.33, 0) -> 40 | S24: =Q24+R24 -> 162 | T24: =ROUND(U23*$P$7, 0) -> 98 | U24: =U23+S24-T24 -> 553 | V24: =U24*149 -> 82397 | W24: =(U24*45)+(V24*0.029)+P24+275 -> 60549.513 | X24: =V24-W24 -> 21847.487 | Y24: =Y23+X24 -> 85142.229 | Z24: =IF(S24>0, P24/S24, 0) -> 203.7037 | AB24: 14 | AC24: =IF(AB24<=12, $AC$3+(AB24-1)*$AC$4, $AC$3+11*$AC$4+(AB24-12)*$AC$5) -> 53000 | AD24: =MAX(ROUND(AC24/$AC$6, 0), 1) -> 241 | AE24: =ROUND(AD24*0.4, 0) -> 96 | AF24: =AD24+AE24 -> 337 | AG24: =ROUND(AH23*$AC$7, 0) -> 156 | AH24: =AH23+AF24-AG24 -> 1482 | AI24: =AH24*149 -> 220818 | AJ24: =(AH24*45)+(AI24*0.029)+AC24+275 -> 126368.72 | AK24: =AI24-AJ24 -> 94449.278 | AL24: =AL23+AK24 -> 471270.63 | AM24: =IF(AF24>0, AC24/AF24, 0) -> 157.27003
B25: 15 | C25: =IF(B25<=12, $C$3+(B25-1)*$C$4, $C$3+11*$C$4+(B25-12)*$C$5) -> 20000 | D25: =MAX(ROUND(C25/$C$6, 0), 1) -> 67 | E25: =ROUND(D25*0.229999999999999, 0) -> 15 | F25: =D25+E25 -> 82 | G25: =ROUND(H24*$C$7, 0) -> 54 | H25: =H24+F25-G25 -> 244 | I25: =H25*149 -> 36356 | J25: =(H25*45)+(I25*0.029)+C25+275 -> 32309.324 | K25: =I25-J25 -> 4046.676 | L25: =L24+K25 -> 2650.807 | M25: =IF(F25>0, C25/F25, 0) -> 243.90244 | O25: 15 | P25: =IF(O25<=12, $P$3+(O25-1)*$P$4, $P$3+11*$P$4+(O25-12)*$P$5) -> 36000 | Q25: =MAX(ROUND(P25/$P$6, 0), 1) -> 133 | R25: =ROUND(Q25*0.33, 0) -> 44 | S25: =Q25+R25 -> 177 | T25: =ROUND(U24*$P$7, 0) -> 111 | U25: =U24+S25-T25 -> 619 | V25: =U25*149 -> 92231 | W25: =(U25*45)+(V25*0.029)+P25+275 -> 66804.699 | X25: =V25-W25 -> 25426.301 | Y25: =Y24+X25 -> 110568.53 | Z25: =IF(S25>0, P25/S25, 0) -> 203.38983 | AB25: 15 | AC25: =IF(AB25<=12, $AC$3+(AB25-1)*$AC$4, $AC$3+11*$AC$4+(AB25-12)*$AC$5) -> 58000 | AD25: =MAX(ROUND(AC25/$AC$6, 0), 1) -> 264 | AE25: =ROUND(AD25*0.4, 0) -> 106 | AF25: =AD25+AE25 -> 370 | AG25: =ROUND(AH24*$AC$7, 0) -> 178 | AH25: =AH24+AF25-AG25 -> 1674 | AI25: =AH25*149 -> 249426 | AJ25: =(AH25*45)+(AI25*0.029)+AC25+275 -> 140838.35 | AK25: =AI25-AJ25 -> 108587.65 | AL25: =AL24+AK25 -> 579858.28 | AM25: =IF(AF25>0, AC25/AF25, 0) -> 156.75676
