Workbook

Sheet Legend
B5: STEP 1: Copy paste screenshot for Ella | C5: Field # | D5: Date | G5: Tag Field | H5: Tag | I5: Description | K5: A. SURFACE CONDITIONS | N5: Sleep_State | O5: Meaning
C6: 1 | D6: Trail_Name | G6: Metabolic | H6: AUTOPHAGY_Deep | I6: Extreme ketone rise + long fasted + altitude stress | N6: SLEEP_EXCELLENT | O6: High score, high HRV, low stress, stable respiration
B7: STEP 2: Ella gives back our 17 metrics | C7: 2 | D7: Distance_mi | G7: Metabolic | H7: AUTOPHAGY_HIGH | I7: Large ketone rise + long fasted effort | K7: Code | L7: Meaning | N7: SLEEP_STRONG | O7: Good score, HRV solid, normal stress
C8: 3 | D8: ElevationGain_ft | G8: Metabolic | H8: AUTOPHAGY_MEDIUM | I8: Moderate ketone increase + long duration | K8: DRY | L8: Standard dry ground, no mud, no snow | N8: SLEEP_MODERATE | O8: Decent score but some recovery constraints
B9: STEP 3: You paste into the Excel dataset | C9: 4 | D9: Duration_min | G9: Metabolic | H9: AUTOPHAGY_LOW | I9: Minimal ketone rise / short session | K9: ROCKY | L9: Frequent rocks, uneven terrain, technical footing | N9: SLEEP_LOW | O9: Low score, low HRV, elevated stress
C10: 5 | D10: Ketone_Start_ppm | G10: Metabolic | H10: GLYCOGEN_CONSERVATION | I10: Low drift / low HR = glycogen sparing | K10: SAND | L10: Sandy or loose soil, energy-inefficient terrain | N10: SLEEP_DEPLETE | O10: Very poor recovery markers
B11: STEP 4: Ella gives the tags (copy paste tags to Ella) | C11: 6 | D11: Ketone_End_ppm | G11: Cardiac | H11: HR_DRIFT_NEGATIVE | I11: Efficiency improving during session | K11: MUDDY | L11: Wet/muddy ground, slipping risk, heavy energy cost
C12: 7 | D12: Avg_HR | G12: Cardiac | H12: HR_DRIFT_LOW | I12: Small positive drift (<5%) | K12: SMOOTH | L12: Well-packed, easy footing, fire road-like
B13: STEP 5: Ella gives one sentence summary | C13: 8 | D13: Max_HR | G13: Cardiac | H13: HR_DRIFT_HIGH | I13: Large drift (>8–10%) | K13: ICE | L13: Icy patches, microspikes required
C14: 9 | D14: HR_Drift_pct | G14: Cardiac | H14: CARDIAC_STABLE | I14: Consistent HR across phases | K14: SNOW | L14: Snow on trail (light or heavy). If deep, add “DEEP_SNOW”
B15: STEP 6: We repeat next hike | C15: 10 | D15: Start_Elevation_ft | G15: Cardiac | H15: CARDIAC_OVERREACH | I15: Sustained high HR / threshold strain | K15: DEEP_SNOW | L15: Fresh powder or deep snow requiring high effort
C16: 11 | D16: Peak_Elevation_ft | G16: Altitude | H16: ALTITUDE_MODERATE | I16: Peak < 7,500 ft | K16: GRAVEL | L16: Fine gravel, rolling stones, slippery small rocks
C17: 12 | D17: Aerobic_Training_Effect | G17: Altitude | H17: ALTITUDE_HIGH | I17: Peak 7,500–10,000 ft
C18: 13 | D18: Anaerobic_Training_Effect | G18: Altitude | H18: ALTITUDE_EXTREME | I18: Peak > 10,000 ft
C19: 14 | D19: Exercise_Load | G19: Altitude | H19: ALTITUDE_ADAPTING | I19: Signs of improving altitude response | K19: B. ENVIRONMENT / BIOME
C20: 15 | D20: Total_Descent_ft | G20: Altitude | H20: ALTITUDE_STRONG | I20: Efficient performance at altitude
C21: 16 | D21: Avg_Temperature_F | G21: Efficiency | H21: ECONOMY_IMPROVING | I21: Lower HR for same vert/time | K21: Code | L21: Meaning
C22: 17 | D22: WorldModel_Summary: | G22: Efficiency | H22: ECONOMY_STABLE | I22: Normal efficiency | K22: FOREST | L22: Shaded forest, tree cover
C23: Tag Field | D23: Metabolic | G23: Efficiency | H23: ECONOMY_FATIGUED | I23: Elevated HR / weaker economy | K23: ALPINE | L23: Exposed high-altitude granite, above treeline
C24: Tag Field | D24: Cardiac | G24: Longevity | H24: LONG_DURATION_STRESS | I24: >3 hours of continuous movement | K24: DESERT | L24: High heat, dry air, sparse vegetation
C25: Tag Field | D25: Altitude | G25: Longevity | H25: HIGH_QUALITY_STRESS | I25: Great physiological load without redline | K25: CHAPARRAL | L25: Southern California brush, shrubs, exposed sun
C26: Tag Field | D26: Efficiency | G26: Longevity | H26: FULL_AUTOPHAGY_EVENT | I26: Ketone rise + long fasted + altitude | K26: RIVER_CROSSING | L26: Water crossings affecting pace + footwork
C27: Tag Field | D27: Longevity | G27: Longevity | H27: PRIMED_FOR_REPAIR | I27: Post-stress recovery window ideal
C28: Tag Field | D28: Recovery / Strain | G28: Recovery / Strain | H28: LOW_STRAIN | I28: Easy physiological load
C29: Tag Field | D29: Engine Pattern | G29: Recovery / Strain | H29: MODERATE_STRAIN | I29: Normal adaptation zone | K29: C. TECHNICAL DIFFICULTY
C30: Summary | D30: WorldModel_Summary: | E30: Short sentence that captures metabolic load, cardiac behavior, and environmental stress. | G30: Recovery / Strain | H30: HIGH_STRAIN | I30: Session with heavy systemic stress
G31: Recovery / Strain | H31: ADAPTATION_READY | I31: HR + load suggests good recovery potential | K31: Code | L31: Meaning
G32: Engine Pattern | H32: ENGINE_STABLE | I32: No major fluctuations; controlled | K32: TECHNICAL | L32: Requires careful foot placement, scrambling
G33: Engine Pattern | H33: ENGINE_IMPROVING | I33: Better metrics than previous similar hike | K33: SCRAMBLE | L33: Class 2–3 scrambling, hands required
G34: Engine Pattern | H34: ENGINE_TAXED | I34: Signs of accumulated fatigue | K34: EXPOSED | L34: Significant drop-offs, mental load
K35: LOW_EXPOSURE | L35: Mostly safe, minimal drop-offs
K36: SMOOTH_GRADE | L36: Switchbacks or consistent grade, low hazard
G37: Hikes | H37: Total | I37: So Far | K37: STEPPED | L37: Stairs or railroad ties, rhythm-breaking
G38: Baldy | H38: 10 | I38: 3
G39: Baden-Powell | H39: 6
G40: San Jacinto | H40: 6 | K40: D. TRAIL TYPE
G41: Icehouse (Ontario + Cucamonga) | H41: 8
G42: Skinsuit | H42: 10 | K42: Code | L42: Meaning
G43: Skyline | H43: 8 | K43: SINGLETRACK | L43: Narrow, one-person trail
G44: San Gorgonio | H44: 4 | K44: FIRE_ROAD | L44: Wide, vehicle-friendly trail
...

Sheet Hikes - High
F1: =+H10 -> Skinsuit to Pleasant's Peak
H2: Skinsuit | I2: Baldy | J2: Baldy | K2: Baldy | L2: Baldy | M2: Skinsuit | N2: Baldy | O2: Baldy | P2: Baldy | Q2: Baldy | R2: Mount Wilson | S2: Mount Wilson | T2: Skinsuit | U2: Mount Wilson | V2: Baldy | W2: Baldy | X2: San Jacinto
D3: Source | E3: Temporal | F3: Field | G3: Field Name | H3: Hike (11/28/2025) | I3: Hike (11/30/2025) | J3: Hike (12/6/2025) | K3: Hike (12/13/2025) | L3: Hike (12/20/2025) | M3: Hike (12/27/2025) | N3: Hike (1/17/2026) | O3: Hike (1/25/2026) | P3: Hike (1/31/2026) | Q3: Hike (2/7/2026) | R3: Hike (2/15/2026) | S3: Hike (2/22/2026) | T3: Hike (3/1/2026) | U3: Hike (3/14/2026) | V3: Hike (3/21/2026) | W3: Hike (3/29/2026) | X3: Hike (4/11/2026)
D4: Mike - field | E4: Pre Hike | F4: Age | G4: Age | H4: 52 | I4: 52 | J4: 52 | K4: 52 | L4: 52 | M4: 52 | N4: 52 | O4: 52 | P4: 52 | Q4: 52 | R4: 52 | S4: 52 | T4: 52 | U4: 52 | V4: 52 | W4: 52 | X4: 52
D5: Mike - field | E5: Pre Hike | F5: Height | G5: Height_Inches | H5: 69 | I5: 69 | J5: 69 | K5: 69 | L5: 69 | M5: 69 | N5: 69 | O5: 69 | P5: 69 | Q5: 69 | R5: 69 | S5: 69 | T5: 69 | U5: 69 | V5: 69 | W5: 69 | X5: 69
D6: Mike - field | E6: Pre Hike | F6: Weight | G6: Weight_IB | H6: 145 | I6: 145 | J6: 145 | K6: 145 | L6: 145 | M6: 145 | N6: 146 | O6: 146 | P6: 146 | Q6: 146 | R6: 146 | S6: 145 | T6: 145 | U6: 145 | V6: 145 | W6: 145 | X6: 145
D7: Mike - field | E7: Hike | F7: Clothing | G7: Clothing | H7: Shorts and Base layer T entire hike. | I7: Shorts and Base Layer T shirt to Summit. Wind Shell summit to mid descent. | J7: Shorts and Base Layer T shirt to Summit. Shell half down and t shirts and shorts to parking lot. | K7: Shorts and Base Layer T shirt entire hike. | L7: Shorts and Base Layer T shirt entire hike. | M7: Shorts and Base layer T entire hike. | N7: Shorts and Base layer T entire hike. | O7: Wind shell till Baldy Saddle. Then, Shorts and Base layer T rest of hike. | P7: Shorts and Base Layer T shirt entire hike. | Q7: Shorts and Base Layer T shirt half of hike. Wind Shell the rest. | R7: Shorts and windshell 75% of hike. Shorts and T 25% remainder. | S7: Shorts and shell till summit. Shorts and T back. | T7: shorts and t shirt | U7: shorts and t shirt | V7: shorts and t shirt | W7: shorts and t shirt | X7: shorts and windshell
D8: Mike - field | E8: Hike | F8: Equipment | G8: Special Equipment | H8: None | I8: Micro Spikes from Tree Line to Summit | J8: Micro Spikes from Tree Line to Summit | K8: None | L8: None | M8: None | N8: Micro Spikes from Tree Line to Summit | O8: Micro Spikes from Tree Line to Summit | P8: None | Q8: None | R8: None | S8: None | T8: None | U8: None | V8: None | W8: None | X8: None
D9: Garmin | E9: Post Hike | F9: Hike | G9: Date | H9: 45989 | I9: 45991 | J9: 45997 | K9: 46004 | L9: 46011 | M9: 46018 | N9: 46039 | O9: 46047 | P9: 46053 | Q9: 46060 | R9: 46068 | S9: 46075 | T9: 46082 | U9: 46095 | V9: 46102 | W9: 46110 | X9: 46123
D10: Garmin | E10: Post Hike | F10: Hike | G10: Trail_Name | H10: Skinsuit to Pleasant's Peak | I10: Ski Hut to Mount Baldy, out and back | J10: Ski Hut to Mount Baldy to Devil's Backbone to Trailhead | K10: Ski Hut to Mount Baldy to Devil's Backbone to Trailhead | L10: Ski Hut to Mount Baldy to Devil's Backbone to Trailhead | M10: Skinsuit to Pleasant's Peak | N10: Ski Hut to Mount Baldy, out and back | O10: Ski Hut to Mount Baldy, out and back | P10: Ski Hut to Mount Baldy, out and back | Q10: Ski Hut to Mount Baldy, out and back | R10: Sturtevant Falls to Mount Wilson | S10: Sturtevant Falls to Mount Wilson | T10: Skinsuit to Hagador Peak | U10: Little Santa Anita to Mount Wilson | V10: Ski Hut to Mount Baldy, out and back | W10: Ski Hut to Mount Baldy to Devil's Backbone to Trailhead | X10: Marion Mountain to San Jacinto and Back.
D11: Garmin | E11: Post Hike | F11: Hike | G11: Distance_mi | H11: 11.65 | I11: 8.62 | J11: 10.74 | K11: 11.05 | L11: 10.67 | M11: 10.1 | N11: 8.76 | O11: 8.3 | P11: 8.65 | Q11: 8.83 | R11: 15 | S11: 13.6 | T11: 9.5 | U11: 14.8 | V11: 8.9 | W11: 9.8 | X11: 12.75
D12: Garmin | E12: Post Hike | F12: Hike | G12: ElevationGain_ft | H12: 3911 | I12: 4058 | J12: 4249 | K12: 4081 | L12: 4098 | M12: 3474 | N12: 4078 | O12: 3996 | P12: 4042 | Q12: 4121 | R12: 4770 | S12: 4501 | T12: 3235 | U12: 5049 | V12: 4121 | W12: 3907 | X12: 4629
D13: Garmin | E13: Post Hike | F13: Hike | G13: Total_Descent_ft | H13: 3888 | I13: 4078 | J13: 4190 | K13: 4101 | L13: 4134 | M13: 3484 | N13: 4088 | O13: 4242 | P13: 4035 | Q13: 4117 | R13: 4738 | S13: 4465 | T13: 3248 | U13: 5052 | V13: 4098 | W13: 3586 | X13: 4610
D14: Mike - field | E14: Hike | F14: Hike | G14: Start Time | H14: 0.41666667 | I14: 0.42361111 | J14: 0.44791667 | K14: 0.35416667 | L14: 0.38541667 | M14: 0.47916667 | N14: 0.35416667 | O14: 0.39583333 | P14: 0.375 | Q14: 0.35416667 | R14: 0.27083333 | S14: 0.26388889 | T14: 0.45833333 | U14: 0.28125 | V14: 0.32291667 | W14: 0.32291667 | X14: 0.32291667
D15: Mike - field | E15: Hike | F15: Hike | G15: End Time | H15: =(H14)+(H16/1440) -> 0.6375 | I15: =(I14)+(I16/1440) -> 0.67083333 | J15: =(J14)+(J16/1440) -> 0.72361111 | K15: =(K14)+(K16/1440) -> 0.61041667 | L15: =(L14)+(L16/1440) -> 0.60555556 | M15: =(M14)+(M16/1440) -> 0.6625 | N15: =(N14)+(N16/1440) -> 0.59375 | O15: =(O14)+(O16/1440) -> 0.63263889 | ... X15: =(X14)+(X16/1440) -> 0.62430556
D16: Garmin | E16: Post Hike | F16: Hike | G16: Duration_min | H16: 318 | I16: 356 | J16: 397 | K16: 369 | L16: 317 | M16: =240+24 -> 264 | N16: =345 -> 345 | O16: =341 -> 341 | P16: =324 -> 324 | Q16: =327 -> 327 | R16: 339 | S16: 335 | T16: 285 | U16: =360+36 -> 396 | V16: =300+28 -> 328 | W16: 310 | X16: 434
D17: Garmin | E17: Post Hike | F17: Hike | G17: Avg_HR | H17: 131 | I17: 132 | J17: 124 | K17: 123 | L17: 130 | M17: 128 | N17: 128 | O17: 128 | P17: 128 | Q17: 128 | R17: 128 | S17: 126 | T17: 130 | U17: 130 | V17: 126 | W17: 129 | X17: 125
D18: Garmin | E18: Post Hike | F18: Hike | G18: Max_HR | H18: 164 | I18: 161 | J18: 155 | K18: 156 | L18: 157 | M18: 157 | N18: 155 | O18: 151 | P18: 150 | Q18: 150 | R18: 165 | S18: 153 | T18: 159 | U18: 158 | V18: 157 | W18: 155 | X18: 159
D19: Garmin | E19: Post Hike | F19: Hike | G19: HR_Drift_pct | H19: -0.0124 | I19: -0.0197 | J19: -0.0055 | K19: 0.0027 | L19: -0.0067 | M19: -0.0159 | N19: -0.0105 | O19: -0.0002 | P19: -0.0152 | Q19: -0.017 | R19: -0.0092 | S19: 0.01 | T19: -0.0283 | U19: -0.0067 | V19: -0.0005 | W19: -0.005 | X19: -0.008
D20: Garmin | E20: Post Hike | F20: Hike | G20: Min_Elevation_ft | H20: 1087 | I20: 6115 | J20: 6115 | K20: 6107 | L20: 6113 | M20: 1070 | N20: 6123 | O20: 5909 | P20: 6129 | Q20: 6114 | R20: 1806 | S20: 1806 | T20: 1089 | U20: 991 | V20: 6136 | W20: 6133 | X20: 6334
D21: Garmin | E21: Post Hike | F21: Hike | G21: Peak_Elevation_ft | H21: 4013 | I21: 10075 | J21: 10075 | K21: 10085 | L21: 10105 | M21: 3893 | N21: 10078 | O21: 10072 | P21: 10111 | Q21: 10089 | R21: 5762 | S21: 5693 | T21: 3898 | U21: 5694 | V21: 10112 | W21: 10080 | X21: 10849
D22: Garmin | E22: Post Hike | F22: Hike | G22: Aerobic_Training_Effect | H22: 5 | I22: 5 | J22: 3.1 | K22: 3.3 | L22: 3.6 | M22: 4 | N22: 3.2 | O22: 3.3 | P22: 3.2 | Q22: 3 | R22: 3.7 | S22: 3.2 | T22: 3.7 | U22: 3.4 | V22: 3 | W22: 3.2 | X22: 3.1
D23: Garmin | E23: Post Hike | F23: Hike | G23: Anaerobic_Training_Effect | H23: 2.4 | I23: 2.5 | J23: 0.3 | K23: 0 | L23: 0 | M23: 0 | N23: 0 | O23: 0.1 | P23: 0 | Q23: 0 | R23: 0.1 | S23: 0 | T23: 0 | U23: 0 | V23: 0 | W23: 0 | X23: 0.1
D24: Garmin | E24: Post Hike | F24: Hike | G24: Exercise_Load | H24: 336 | I24: 438 | J24: 103 | K24: 102 | L24: 123 | M24: 139 | N24: 81 | O24: 85 | P24: 76 | Q24: 63 | R24: 121 | S24: 79 | T24: 115 | U24: 94 | V24: 62 | W24: 79 | X24: 71
D25: Garmin | E25: Post Hike | F25: Hike | G25: Min Temp | H25: 70 | I25: 41 | J25: 48 | K25: 59 | L25: 54 | M25: 54 | N25: 63 | O25: 50 | P25: 61 | Q25: 45 | R25: 54 | S25: 48 | T25: 79 | U25: 61 | V25: 59 | W25: 57 | X25: 46
D26: Garmin | E26: Post Hike | F26: Hike | G26: Max Temp | H26: 91 | I26: 81 | J26: 82 | K26: 82 | L26: 79 | M26: 88 | N26: 82 | O26: 75 | P26: 84 | Q26: 77 | R26: 77 | S26: 84 | T26: 97 | U26: 91 | V26: 86 | W26: 86 | X26: 75
D27: Garmin | E27: Post Hike | F27: Hike | G27: Avg_Temperature_F | H27: 81 | I27: 60 | J27: 67 | K27: 72 | L27: 68 | M27: 67 | N27: 72 | O27: 59 | P27: 71 | Q27: 60 | R27: 60 | S27: 64 | T27: 87 | U27: 75 | V27: 71 | W27: 70 | X27: 59
D28: Garmin | E28: Post Hike | F28: Hike | G28: Terrain_Condition | H28: Rocky, Technical, Max_Exposure | I28: Rocky, Technical, Partially Exposed | J28: Rocky, Technical, Partially Exposed | K28: Rocky, Technical, Partially Exposed | L28: Rocky, Technical, Partially Exposed | M28: Rocky, Technical, Max_Exposure | N28: Rocky, Technical, Partially Exposed | O28: Rocky, Technical, Partially Exposed | P28: Rocky, Technical, Partially Exposed | Q28: Rocky, Technical, Partially Exposed | R28: Rocky, Alpine, River Crossings, exposed switchbacks | S28: Rocky, Alpine, River Crossings, exposed switchbacks | T28: Rocky, Technical, Max_Exposure | U28: Dirt, Rocky, Exposed | V28: Rocky, Technical, Partially Exposed | W28: Rocky, Technical, Partially Exposed | X28: Steep, Rocky, Technical, Partially Exposed
D29: Garmin | E29: Post Hike | F29: Hike - Week Of | G29: VO2Max | H29: 46 | I29: 46 | J29: 46 | K29: 46 | L29: 46 | M29: 46 | N29: 46 | O29: 46 | P29: 46 | Q29: 46 | R29: 46 | S29: 46 | T29: 46 | U29: 46 | V29: 46 | W29: 46 | X29: 46
D30: Ella Estimated for Elevation | E30: Post Hike | F30: Hike - Week Of | G30: VO2Max | H30: 50 to 52 | I30: 50 to 52 | J30: 50 to 52 | K30: 50 to 52 | L30: 50 to 52 | M30: 50 to 52 | N30: 50 to 52 | O30: 50 to 52 | P30: 50 to 52 | Q30: 50 to 52 | R30: 50 to 52 | S30: 50 to 52 | T30: 50 to 52 | U30: 50 to 52 | V30: 50 to 52 | W30: 50 to 52 | X30: 50 to 52
D31: Mike - Field | E31: Post Hike | F31: Terrain | G31: Surface Conditions | H31: Dry, Gravel | I31: Snow, Icy | J31: Sloshy Snow | K31: Snow, Icy | L31: Mixed. No more snow | M31: Wet, Clay | N31: Snow, Icy | O31: Snow, Icy | P31: Snow, Icy and Slippery | Q31: Partial Snow | R31: Rocky, Slippery, Mixed | S31: Rocky, Mixed, Snow last 2 miles to peak | T31: Slippery and dry dirt | U31: Dry, Gravel | V31: Mixed. No more snow | W31: Mixed. No more snow | X31: Mixed
D32: Mike - Field | E32: Post Hike | F32: Terrain | G32: Environment | H32: CHAPARRAL | I32: Alpine | J32: Alpine | K32: Alpine | L32: Alpine | M32: CHAPARRAL | N32: Alpine | O32: Alpine | P32: Alpine | Q32: Alpine | R32: Alpine | S32: Alpine | T32: CHAPARRAL | U32: CHAPARRAL | V32: Alpine | W32: Alpine | X32: Alpine
D33: Mike - Field | E33: Post Hike | F33: Terrain | G33: Technical Difficulty | H33: Steep, Technical | I33: Steep, Technical | J33: Steep, Technical, Fire Road | K33: Steep, Technical, Fire Road | L33: Steep, Technical, Fire Road | M33: Steep, Technical | N33: Steep, Extremely Technical from Post Flooding | O33: Steep, Extremely Technical from Post Flooding | P33: Steep, Extremely Technical from Post Flooding | Q33: Steep, Extremely Technical | R33: Steep, Technical | S33: Steep, Technical | T33: Steep, Technical | U33: Steep, Technical | V33: Steep, Technical | W33: Steep, Technical | X33: Steep, Technical, Scrambling at Peak
D34: Mike - Field | E34: Post Hike | F34: Terrain | G34: Trail Type | H34: Mixed_Trail | I34: Mixed_Trail | J34: Mixed_Trail | K34: Mixed_Trail | L34: Mixed_Trail | M34: Mixed_Trail | N34: Mixed_Trail | O34: Mixed_Trail | P34: Mixed_Trail | Q34: Mixed_Trail | R34: Mixed_Trail | S34: Mixed_Trail | T34: Mixed_Trail | U34: Mixed_Trail | V34: Mixed_Trail | W34: Mixed_Trail | X34: Mixed_Trail
D35: Mike - Field | E35: Post Hike | F35: Weather | G35: Temp Range | H35: 65F to 70F | I35: 45F to 55F | J35: 45F to 55F | K35: 55F to 65F | L35: 50F to 65F | M35: 55F to 65F | N35: 45F to 55F | O35: 40F to 50F | P35: 50F to 65F | Q35: 45F to 55F | R35: 45F to 55F | S35: 50F to 60F | T35: 80F to 85F | U35: 65F to 85F | V35: 55F to 75F | W35: 50F to 70F | X35: 37F to 55F
D36: Mike - Field | E36: Post Hike | F36: Weather | G36: Wind | H36: Light | I36: Moderate | J36: Strong | K36: Calm | L36: Strong | M36: Light | N36: Moderate | O36: Moderate | P36: Calm | Q36: Strong | R36: Strong | S36: Calm | T36: Light | U36: Light | V36: Light | W36: Strong | X36: Strong
D37: Mike - Field | E37: Post Hike | F37: Weather | G37: Sun | H37: Light | I37: Moderate | J37: Strong | K37: Strong | L37: Moderate | M37: Light | N37: Strong | O37: Strong | P37: Strong | Q37: Moderate | R37: Cloudy | S37: Moderate | T37: Strong | U37: Moderate | V37: Strong | W37: Strong | X37: Moderate
D38: Mike - Field | E38: Post Hike | F38: Electrolytes | G38: Electrolyte Packs Used | H38: 1 | I38: 2 | J38: 2 | K38: 2 | L38: 1.5 | M38: 2 | N38: 1.5 | O38: 2 | P38: 2 | Q38: 2 | R38: 2 | S38: 2 | T38: 2 | U38: 2 | V38: 2 | W38: 2 | X38: 2
D39: Mike - Field | E39: Post Hike | F39: Electrolytes | G39: Electrolyte Type | H39: Moderate | I39: Moderate | J39: High | K39: High | L39: Moderate | M39: Moderate | N39: High | O39: Moderate | P39: Moderate | Q39: Moderate | R39: Moderate | S39: Moderate | T39: Moderate | U39: High | V39: High | W39: High | X39: High
D40: Mike - Field | E40: Pre Hike | F40: Coffee | G40: Coffee | H40: Yes | I40: No | J40: No | K40: No | L40: No | M40: Yes | N40: Yes | O40: No | P40: No | Q40: No | R40: No | S40: No | T40: None | U40: None | V40: No | W40: No | X40: No
...

Sheet Sheet4
C4: -0.0124 | D4: -0.0197 | E4: -0.0055 | F4: 0.0027 | G4: -0.0067 | H4: -0.0159 | I4: -0.0105 | J4: -0.0002 | K4: -0.0152 | L4: -0.017 | M4: -0.0092 | N4: 0.01 | O4: -0.0283 | P4: -0.0067 | Q4: -0.0005

Sheet HikeWorldModel
A1: Hike_ID | B1: Date | C1: Trail_Name | D1: Hike_Type | E1: Age | F1: Height_Inches | G1: Weight_LB | H1: Clothing | I1: Special_Equipment | J1: Coffee | K1: Distance_mi | L1: ElevationGain_ft | M1: Total_Descent_ft | N1: Duration_min | O1: Start_Time | P1: End_Time | Q1: Avg_HR | R1: Max_HR | S1: HR_Drift_pct | T1: Aerobic_Training_Effect | U1: Anaerobic_Training_Effect | V1: Exercise_Load | W1: Min_Elevation_ft | X1: Peak_Elevation_ft | Y1: VO2Max_Garmin | Z1: VO2Max_Ella_Est | AA1: Min_Temp_F | AB1: Max_Temp_F | AC1: Avg_Temp_F | AD1: Terrain_Condition | AE1: Surface_Conditions | AF1: Environment | AG1: Technical_Difficulty | AH1: Trail_Type | AI1: Temp_Range | AJ1: Wind | AK1: Sun | AL1: Electrolyte_Packs_Used | AM1: Electrolyte_Type | AN1: Ketone_Wake_ppm | AO1: Ketone_Start_ppm | AP1: Ketone_Peak_ppm | AQ1: Ketone_End_ppm | AR1: Ketone_DayAfter_ppm | AS1: Ketone_2DaysAfter_ppm | AT1: Tag_Metabolic | AU1: Tag_Cardiac | AV1: Tag_Altitude | AW1: Tag_Efficiency | AX1: Tag_Longevity | AY1: Tag_Recovery_Strain | AZ1: Tag_Engine_Pattern | BA1: WorldModel_Summary | BB1: PreSleep_Score | BC1: PreSleep_Total_min | BD1: PreSleep_Deep_min | BE1: PreSleep_REM_min | BF1: PreSleep_Light_min | BG1: PreSleep_Awake_min | BH1: PreSleep_HR_Resting | BI1: PreSleep_Avg_Overnight_HR | BJ1: PreSleep_Overnight_HRV | BK1: PreSleep_Respiratory_Rate | BL1: PreSleep_Stress_Avg | BM1: PreSleep_Skin_Temp_Change_F | BN1: PreSleep_Ella_Quality | BO1: PreSleep_Ella_Recovery | BP1: PreSleep_Ella_Autonomic | BQ1: PreSleep_Ella_Depth | BR1: PreSleep_Ella_Summary | BS1: PostSleep_Score | BT1: PostSleep_Total_min | BU1: PostSleep_Deep_min | BV1: PostSleep_REM_min | BW1: PostSleep_Light_min | BX1: PostSleep_Awake_min | BY1: PostSleep_HR_Resting | BZ1: PostSleep_Avg_Overnight_HR | CA1: PostSleep_Overnight_HRV | CB1: PostSleep_Respiratory_Rate | CC1: PostSleep_Stress_Avg | CD1: PostSleep_Skin_Temp_Change_F | CE1: PostSleep_Ella_Quality | CF1: PostSleep_Ella_Recovery | CG1: PostSleep_Ella_Autonomic | CH1: PostSleep_Ella_Depth | CI1: PostSleep_Ella_Summary | CJ1: Day2Sleep_Score | CK1: Day2Sleep_Total_min | CL1: Day2Sleep_Deep_min | CM1: Day2Sleep_REM_min | CN1: Day2Sleep_Light_min | CO1: Day2Sleep_Awake_min | CP1: Day2Sleep_HR_Resting | CQ1: Day2Sleep_Avg_Overnight_HR | CR1: Day2Sleep_Overnight_HRV | CS1: Day2Sleep_Respiratory_Rate | CT1: Day2Sleep_Stress_Avg | CU1: Day2Sleep_Skin_Temp_Change_F | CV1: Day2Sleep_Ella_Quality | CW1: Day2Sleep_Ella_Recovery | CX1: Day2Sleep_Ella_Autonomic | CY1: Day2Sleep_Ella_Depth | CZ1: Day2Sleep_Ella_Summary | DA1: Latent_Metabolic_Flexibility | DB1: Latent_Autophagy_Depth | DC1: Latent_Cardiac_Efficiency | DD1: Latent_Altitude_Adaptation | DE1: Latent_Recovery_Debt | DF1: Latent_Mechanical_Stress | DG1: Latent_Engine_Stability | DH1: Narr_Metabolic_Flexibility | DI1: Narr_Autophagy_Depth | DJ1: Narr_Cardiac_Efficiency | DK1: Narr_Altitude_Adaptation | DL1: Narr_Recovery_Debt | DM1: Narr_Mechanical_Stress | DN1: Narr_Engine_Stability | DO1: Primary_Adaptation_Vector | DP1: Stability_Index | DQ1: Rolling_28Day_Load | DR1: Rolling_28Day_Altitude_Exposure | DS1: Rolling_28Day_Avg_Ketone_Peak
A2: INT|Auto | B2: DATE|mm/dd/yyyy | C2: TEXT|Trail name | D2: ENUM|HIGH,LOW | E2: INT|years | F2: INT|inches | G2: INT|pounds | H2: TEXT|description | I2: TEXT|description | J2: ENUM|YES,NO | K2: FLOAT|miles | L2: INT|feet | M2: INT|feet | N2: INT|minutes | O2: TIME|hh:mm | P2: TIME|hh:mm | Q2: INT|bpm | R2: INT|bpm | S2: FLOAT|decimal_pct | T2: FLOAT|0-5 | U2: FLOAT|0-5 | V2: INT|load_units | W2: INT|feet | X2: INT|feet | Y2: INT|ml/kg/min | Z2: TEXT|range_est | AA2: INT|°F | AB2: INT|°F | AC2: INT|°F | AD2: TEXT|multi_tag | AE2: TEXT|multi_tag | AF2: ENUM|Legend | AG2: TEXT|multi_tag | AH2: ENUM|Legend | AI2: TEXT|range | AJ2: ENUM|CALM,LIGHT,MODERATE,STRONG | AK2: ENUM|LIGHT,MODERATE,STRONG | AL2: FLOAT|count | AM2: ENUM|LOW,MODERATE,HIGH | AN2: FLOAT|ppm | AO2: FLOAT|ppm | AP2: FLOAT|ppm | AQ2: FLOAT|ppm | AR2: FLOAT|ppm | AS2: FLOAT|ppm | AT2: ENUM|Legend | AU2: ENUM|Legend | AV2: ENUM|Legend | AW2: ENUM|Legend | AX2: ENUM|Legend | AY2: ENUM|Legend | AZ2: ENUM|Legend | BA2: TEXT|narrative | BB2: INT|0-100 | BC2: INT|minutes | BD2: INT|minutes | BE2: INT|minutes | BF2: INT|minutes | BG2: INT|minutes | BH2: INT|bpm | BI2: INT|bpm | BJ2: INT|ms | BK2: INT|breaths/min | BL2: INT|stress_score | BM2: FLOAT|°F | BN2: ENUM|Quality | BO2: ENUM|Recovery | BP2: ENUM|Autonomic | BQ2: ENUM|Depth | BR2: TEXT|narrative | BS2: INT|0-100 | BT2: INT|minutes | BU2: INT|minutes | BV2: INT|minutes | BW2: INT|minutes | BX2: INT|minutes | BY2: INT|bpm | BZ2: INT|bpm | CA2: INT|ms | CB2: INT|breaths/min | CC2: INT|stress_score | CD2: FLOAT|°F | CE2: ENUM|Quality | CF2: ENUM|Recovery | CG2: ENUM|Autonomic | CH2: ENUM|Depth | CI2: TEXT|narrative | CJ2: INT|0-100 | CK2: INT|minutes | CL2: INT|minutes | CM2: INT|minutes | CN2: INT|minutes | CO2: INT|minutes | CP2: INT|bpm | CQ2: INT|bpm | CR2: INT|ms | CS2: INT|breaths/min | CT2: INT|stress_score | CU2: FLOAT|°F | CV2: ENUM|Quality | CW2: ENUM|Recovery | CX2: ENUM|Autonomic | CY2: ENUM|Depth | CZ2: TEXT|narrative | DA2: FLOAT|1-10 | DB2: FLOAT|1-10 | DC2: FLOAT|1-10 | DD2: FLOAT|1-10 | DE2: FLOAT|1-10 | DF2: FLOAT|1-10 | DG2: FLOAT|1-10 | DH2: TEXT|narrative | DI2: TEXT|narrative | DJ2: TEXT|narrative | DK2: TEXT|narrative | DL2: TEXT|narrative | DM2: TEXT|narrative | DN2: TEXT|narrative | DO2: ENUM|METABOLIC,ALTITUDE,CARDIAC,RECOVERY,CONSOLIDATION,REPAIR_BIAS | DP2: FLOAT|1-10 | DQ2: INT|load_units | DR2: INT|feet | DS2: FLOAT|ppm
A3: System | B3: Garmin | C3: Garmin | D3: Mike | E3: Mike | F3: Mike | G3: Mike | H3: Mike | I3: Mike | J3: Mike | K3: Garmin | L3: Garmin | M3: Garmin | N3: Garmin | O3: Mike | P3: Mike | Q3: Garmin | R3: Garmin | S3: Garmin | T3: Garmin | U3: Garmin | V3: Garmin | W3: Garmin | X3: Garmin | Y3: Garmin | Z3: Ella | AA3: Garmin | AB3: Garmin | AC3: Garmin | AD3: Garmin | AE3: Mike | AF3: Mike | AG3: Mike | AH3: Mike | AI3: Mike | AJ3: Mike | AK3: Mike | AL3: Mike | AM3: Mike | AN3: Ketoscan | AO3: Ketoscan | AP3: Ketoscan | AQ3: Ketoscan | AR3: Ketoscan | AS3: Ketoscan | AT3: Ella | AU3: Ella | AV3: Ella | AW3: Ella | AX3: Ella | AY3: Ella | AZ3: Ella | BA3: Ella | BB3: Garmin | BC3: Garmin | BD3: Garmin | BE3: Garmin | BF3: Garmin | BG3: Garmin | BH3: Garmin | BI3: Garmin | BJ3: Garmin | BK3: Garmin | BL3: Garmin | BM3: Garmin | BN3: Ella | BO3: Ella | BP3: Ella | BQ3: Ella | BR3: Ella | BS3: Garmin | BT3: Garmin | BU3: Garmin | BV3: Garmin | BW3: Garmin | BX3: Garmin | BY3: Garmin | BZ3: Garmin | CA3: Garmin | CB3: Garmin | CC3: Garmin | CD3: Garmin | CE3: Ella | CF3: Ella | CG3: Ella | CH3: Ella | CI3: Ella | CJ3: Garmin | CK3: Garmin | CL3: Garmin | CM3: Garmin | CN3: Garmin | CO3: Garmin | CP3: Garmin | CQ3: Garmin | CR3: Garmin | CS3: Garmin | CT3: Garmin | CU3: Garmin | CV3: Ella | CW3: Ella | CX3: Ella | CY3: Ella | CZ3: Ella | DA3: Ella | DB3: Ella | DC3: Ella | DD3: Ella | DE3: Ella | DF3: Ella | DG3: Ella | DH3: Ella | DI3: Ella | DJ3: Ella | DK3: Ella | DL3: Ella | DM3: Ella | DN3: Ella | DO3: Ella_Inferred | DP3: Computed | DQ3: Computed | DR3: Computed | DS3: Computed
A4: 1 | B4: 45989 | C4: Skinsuit to Pleasant's Peak | D4: HIGH | E4: 52 | F4: 69 | G4: ='Hikes - High'!H6 -> 145 | H4: Shorts and Base layer T entire hike. | I4: None | J4: YES | K4: 11.65 | L4: 3911 | M4: 3888 | N4: 318 | O4: 0.41666667 | P4: 0.6375 | Q4: 131 | R4: 164 | S4: -0.0124 | T4: 5 | U4: 2.4 | V4: 336 | W4: 1087 | X4: 4013 | Y4: 46 | Z4: 50 to 52 | AA4: 70 | AB4: 91 | AC4: 81 | AD4: Rocky, Technical, Max_Exposure | AE4: Dry, Gravel | AF4: CHAPARRAL | AG4: Steep, Technical | AH4: MIXED_TRAIL | AI4: 65F to 70F | AJ4: LIGHT | AK4: LIGHT | AL4: 1 | AM4: MODERATE | AN4: 1.1 | AO4: 0.7 | AP4: 1.7 | AQ4: 4.6 | AR4: 1.5 | AS4: 1.3 | AT4: AUTOPHAGY_MEDIUM | AU4: HR_DRIFT_NEGATIVE | AV4: ALTITUDE_MODERATE | AW4: ECONOMY_IMPROVING | AX4: LONG_DURATION_STRESS | AY4: MODERATE_STRAIN | AZ4: ENGINE_STABLE | BA4: Fasted autophagy hike with rising metabolic efficiency, negative HR drift, moderate altitude stress, and stable engine pattern | BB4: 87 | BC4: 438 | BD4: 73 | BE4: 96 | BF4: 269 | BG4: 15 | BH4: 60 | BI4: 65 | BJ4: 42 | BK4: 15 | BL4: 12 | BM4: Calibrating | BN4: QUALITY_HIGH | BO4: RECOVERY_HIGH | BP4: AUTONOMIC_STABLE | BQ4: DEPTH_HIGH | BR4: High-quality sleep with strong recovery markers, stable autonomic tone, and deep restorative phases. | BS4: 48 | BT4: 325 | BU4: 85 | BV4: 31 | BW4: 209 | BX4: 40 | BY4: 65 | BZ4: 74 | CA4: 35 | CB4: 15 | CC4: 19 | CD4: Calibrating | CE4: QUALITY_POOR | CF4: RECOVERY_LOW | CG4: AUTONOMIC_STRAINED | CH4: DEPTH_HIGH | CI4: Poor overall sleep with low recovery and strained autonomic tone, but strong deep sleep indicating active overnight repair. | CJ4: 79 | CK4: 297 | CL4: 71 | CM4: 91 | CN4: 298 | CO4: 52 | CP4: 65 | CQ4: 69 | CR4: 35 | CS4: 15 | CT4: 19 | CU4: 0.4 | CV4: QUALITY_HIGH | CW4: RECOVERY_GOOD | CX4: AUTONOMIC_STABLE | CY4: DEPTH_HIGH | CZ4: Solid restorative sleep with stable autonomic tone, good deep and REM distribution. | DA4: 7 | DB4: 7 | DC4: 7 | DD4: 6 | DE4: 5 | DF4: 6 | DG4: 8 | DH4: Moderate end ketones (4.6 ppm), weaker start (0.7), limited retention | DI4: Fasted + rising ketones, but shallow peak and modest carryover | DJ4: Negative HR drift (-9.19%) with avg HR 131 under load | DK4: Moderate altitude, clear physiologic response but manageable | DL4: Poor post-hike sleep but full Day-2 recovery | DM4: Steep, technical terrain with exposure, no instability | DN4: Consistent HR behavior, clean recovery, no oscillation | DO4: METABOLIC | DP4: 7.8 | DQ4: 336 | DR4: 4013 | DS4: 1.7
A5: 2 | B5: 45991 | C5: Ski Hut to Mount Baldy, out and back | D5: HIGH | E5: 52 | F5: 69 | G5: ='Hikes - High'!I6 -> 145 | H5: Shorts and Base Layer T shirt to Summit. Wind Shell summit to mid descent. | I5: Micro Spikes from Tree Line to Summit | J5: NO | K5: 8.62 | L5: 4058 | M5: 4078 | N5: 356 | O5: 0.42361111 | P5: 0.67083333 | Q5: 132 | R5: 161 | S5: -0.0197 | T5: 5 | U5: 2.5 | V5: 438 | W5: 6115 | X5: 10075 | Y5: 46 | Z5: 50 to 52 | AA5: 41 | AB5: 81 | AC5: 60 | AD5: Rocky, Technical, Partially Exposed | AE5: Snow, Icy | AF5: ALPINE | AG5: Steep, Technical | AH5: MIXED_TRAIL | AI5: 45F to 55F | AJ5: MODERATE | AK5: MODERATE | AL5: 2 | AM5: MODERATE | AN5: 1.3 | AO5: 1.5 | AP5: 4 | AQ5: 11 | AR5: 1.2 | AS5: NA | AT5: AUTOPHAGY_DEEP | AU5: HR_DRIFT_NEGATIVE | AV5: ALTITUDE_EXTREME | AW5: ECONOMY_IMPROVING | AX5: LONG_DURATION_STRESS | AY5: HIGH_STRAIN | AZ5: ENGINE_STABLE | BA5: Deep autophagy activation with efficient cardiac control (negative HR drift), high-altitude adaptation, strong metabolic efficiency, and stable engine pattern under elevated training load. | BB5: 79 | BC5: 418 | BD5: 71 | BE5: 91 | BF5: 256 | BG5: 19 | BH5: 65 | BI5: 69 | BJ5: 35 | BK5: 15 | BL5: 19 | BM5: 0.4 | BN5: QUALITY_HIGH | BO5: RECOVERY_GOOD | BP5: AUTONOMIC_STABLE | BQ5: DEPTH_HIGH | BR5: Solid restorative sleep with stable autonomic tone, good deep and REM distribution, slightly elevated resting HR, and moderate HRV. | BS5: 36 | BT5: 216 | BU5: 35 | BV5: 0 | BW5: 181 | BX5: 16 | BY5: 67 | BZ5: 76 | CA5: 25 | CB5: 18 | CC5: 36 | CD5: -0.4 | CE5: QUALITY_POOR | CF5: RECOVERY_LOW | CG5: AUTONOMIC_STRAINED | CH5: DEPTH_HIGH | CI5: Poor post-hike sleep with suppressed HRV, elevated resting HR, minimal deep sleep, and low recovery markers. | CJ5: 79 | CK5: 420 | CL5: 85 | CM5: 97 | CN5: 238 | CO5: 26 | CP5: 62 | CQ5: 68 | CR5: 37 | CS5: 16 | CT5: 17 | CU5: 0 | CV5: QUALITY_HIGH | CW5: RECOVERY_GOOD | CX5: AUTONOMIC_STABLE | CY5: DEPTH_HIGH | CZ5: Solid restorative sleep with stable autonomic tone, high deep-sleep volume, strong REM distribution. | DA5: 9 | DB5: 9 | DC5: 8.5 | DD5: 8 | DE5: 6 | DF5: 7 | DG5: 8 | DH5: Strong peak (4 ppm) and very high end ketones (11 ppm) | DI5: Deep autophagy with strong post-exercise ketosis despite strain | DJ5: Sustained negative HR drift (-8.42%) at altitude | DK5: High altitude absorbed without HR instability | DL5: Significant post-hike strain, but complete Day-2 reset | DM5: Snow, ice, technical terrain, higher duration | DN5: Stable engine under escalated altitude + cold load | DO5: METABOLIC | DP5: 8.1 | DQ5: 774 | DR5: 14088 | DS5: 2.85
A6: 3 | B6: 45997 | C6: Ski Hut to Mount Baldy to Devil's Backbone to Trailhead | D6: HIGH | E6: 52 | F6: 69 | G6: ='Hikes - High'!J6 -> 145 | H6: Shorts and Base Layer T shirt to Summit. Shell half down and t shirts and shorts to parking lot. | I6: Micro Spikes from Tree Line to Summit | J6: NO | K6: 10.74 | L6: 4249 | M6: 4190 | N6: 397 | O6: 0.44791667 | P6: 0.72361111 | Q6: 124 | R6: 155 | S6: -0.0055 | T6: 3.1 | U6: 0.3 | V6: 103 | W6: 6115 | X6: 10075 | Y6: 46 | Z6: 50 to 52 | AA6: 48 | AB6: 82 | AC6: 67 | AD6: Rocky, Technical, Partially Exposed | AE6: Sloshy Snow | AF6: ALPINE | AG6: Steep, Technical, Fire Road | AH6: MIXED_TRAIL | AI6: 45F to 55F | AJ6: STRONG | AK6: STRONG | AL6: 2 | AM6: HIGH | AN6: 1.8 | AO6: 1.9 | AP6: 3.1 | AQ6: 13 | AR6: 2.6 | AS6: 2 | AT6: AUTOPHAGY_DEEP | AU6: HR_DRIFT_NEGATIVE | AV6: ALTITUDE_EXTREME | AW6: ECONOMY_IMPROVING | AX6: LONG_DURATION_STRESS | AY6: HIGH_STRAIN | AZ6: ENGINE_STABLE | BA6: Deep autophagy activation with controlled cardiac load (continued negative HR drift), efficient energy utilization in cold aerobic conditions, improved next-day ketone retention, and stable engine pattern across technical snow and exposed ridgeline terrain. | BB6: 86 | BC6: 429 | BD6: 64 | BE6: 91 | BF6: 274 | BG6: 2 | BH6: 61 | BI6: 64 | BJ6: 38 | BK6: 15 | BL6: 14 | BM6: 0.3 | BN6: QUALITY_LOW | BO6: RECOVERY_MODERATE | BP6: AUTONOMIC_STABLE | BQ6: DEPTH_LOW | BR6: Short sleep duration with reduced deep and REM phases, lower HRV, and partial overnight recovery. | BS6: 57 | BT6: 274 | BU6: 50 | BV6: 44 | BW6: 180 | BX6: 20 | BY6: 61 | BZ6: 69 | CA6: 28 | CB6: 17 | CC6: 25 | CD6: -0.7 | CE6: QUALITY_POOR | CF6: RECOVERY_LOW | CG6: AUTONOMIC_STRAINED | CH6: DEPTH_HIGH | CI6: Poor post-hike sleep with suppressed HRV, elevated resting HR, minimal deep sleep, and low recovery markers. | CJ6: 81 | CK6: 398 | CL6: 59 | CM6: 88 | CN6: 251 | CO6: 15 | CP6: 59 | CQ6: 64 | CR6: 42 | CS6: 15 | CT6: 13 | CU6: -0.4 | CV6: QUALITY_HIGH | CW6: RECOVERY_GOOD | CX6: AUTONOMIC_STABLE | CY6: DEPTH_HIGH | CZ6: Solid restorative sleep with stable autonomic tone, strong REM distribution, elevated deep-sleep proportion. | DA6: 9.5 | DB6: 9.5 | DC6: 9 | DD6: 8 | DE6: 6 | DF6: 7 | DG6: 8 | DH6: Highest wake/start/end ketones (1.8 → 13 ppm) with retention | DI6: Deep autophagy + improved Day-1 & Day-2 ketone persistence | DJ6: Lowest avg HR (124) with negative drift (-6.0%) | DK6: Same elevation, reduced physiological cost | DL6: Sleep debt present but fully resolved by Day-2 | DM6: Long duration, snow, exposed ridgeline, mixed terrain | DN6: No degradation despite cumulative load | DO6: METABOLIC | DP6: 7.4 | DQ6: 877 | DR6: 24163 | DS6: 2.93
A7: 4 | B7: 46004 | C7: Ski Hut to Mount Baldy to Devil's Backbone to Trailhead | D7: HIGH | E7: 52 | F7: 69 | G7: ='Hikes - High'!K6 -> 145 | H7: Shorts and Base Layer T shirt entire hike. | I7: None | J7: NO | K7: 11.05 | L7: 4081 | M7: 4101 | N7: 369 | O7: 0.35416667 | P7: 0.61041667 | Q7: 123 | R7: 156 | S7: 0.0027 | T7: 3.3 | U7: 0 | V7: 102 | W7: 6107 | X7: 10085 | Y7: 46 | Z7: 50 to 52 | AA7: 59 | AB7: 82 | AC7: 72 | AD7: Rocky, Technical, Partially Exposed | AE7: Snow, Icy | AF7: ALPINE | AG7: Steep, Technical, Fire Road | AH7: MIXED_TRAIL | AI7: 55F to 65F | AJ7: CALM | AK7: STRONG | AL7: 2 | AM7: HIGH | AN7: 1.7 | AO7: 2.2 | AP7: 2 | AQ7: 5.8 | AR7: 1.4 | AS7: NA | AT7: AUTOPHAGY_HIGH | AU7: HR_DRIFT_NEGATIVE | AV7: ALTITUDE_EXTREME | AW7: ECONOMY_IMPROVING | AX7: LONG_DURATION_STRESS | AY7: MODERATE_STRAIN | AZ7: ENGINE_STABLE | BA7: Sustained autophagy activation with negative heart rate drift and reduced metabolic cost, reflecting improving efficiency and cardiovascular control at moderate altitude. | BB7: 73 | BC7: 360 | BD7: 73 | BE7: 49 | BF7: 238 | BG7: 29 | BH7: 58 | BI7: 62 | BJ7: 38 | BK7: 15 | BL7: 11 | BM7: 0 | BN7: QUALITY_MODERATE | BO7: RECOVERY_GOOD | BP7: AUTONOMIC_STABLE | BQ7: DEPTH_HIGH | BR7: Short sleep duration with reduced deep and REM phases, lower HRV, and partial overnight recovery. | BS7: 69 | BT7: 361 | BU7: 77 | BV7: 38 | BW7: 246 | BX7: 27 | BY7: 61 | BZ7: 66 | CA7: 31 | CB7: 17 | CC7: 21 | CD7: -0.3 | CE7: QUALITY_POOR | CF7: RECOVERY_LOW | CG7: AUTONOMIC_STRAINED | CH7: DEPTH_HIGH | CI7: Poor post-hike sleep marked by reduced REM duration and continued autonomic strain, but with preserved deep sleep. | CJ7: 63 | CK7: 322 | CL7: 61 | CM7: 21 | CN7: 240 | CO7: 9 | CP7: 62 | CQ7: 66 | CR7: 37 | CS7: 16 | CT7: 17 | CU7: -0.3 | CV7: QUALITY_MODERATE | CW7: RECOVERY_PARTIAL | CX7: AUTONOMIC_STABLE | CY7: DEPTH_HIGH | CZ7: Moderately restorative sleep with stable autonomic tone and preserved deep-sleep repair, but shortened total duration. | DA7: 8 | DB7: 7.5 | DC7: 9 | DD7: 8.5 | DE7: 7 | DF7: 6 | DG7: 8.5 | DH7: Lower peak & end ketones (2 → 5.8 ppm) + weaker retention | DI7: Still autophagic, but REM suppression + lower end ketones reduce depth | DJ7: Lowest avg HR (123) + continued negative drift = excellent | DK7: Same peak elevation, lower physiological cost | DL7: Day-2 REM collapse + partial recovery increases debt | DM7: No spikes, calmer weather, smoother descent | DN7: Despite strain, variance across systems tightened | DO7: CONSOLIDATION | DP7: 6.4 | DQ7: 979 | DR7: 34248 | DS7: 2.7
A8: 5 | B8: 46011 | C8: Ski Hut to Mount Baldy to Devil's Backbone to Trailhead | D8: HIGH | E8: 52 | F8: 69 | G8: ='Hikes - High'!L6 -> 145 | H8: Shorts and Base Layer T shirt entire hike. | I8: None | J8: NO | K8: 10.67 | L8: 4098 | M8: 4134 | N8: 317 | O8: 0.38541667 | P8: 0.60555556 | Q8: 130 | R8: 157 | S8: -0.0067 | T8: 3.6 | U8: 0 | V8: 123 | W8: 6113 | X8: 10105 | Y8: 46 | Z8: 50 to 52 | AA8: 54 | AB8: 79 | AC8: 68 | AD8: Rocky, Technical, Partially Exposed | AE8: Mixed. No more snow | AF8: ALPINE | AG8: Steep, Technical, Fire Road | AH8: MIXED_TRAIL | AI8: 50F to 65F | AJ8: STRONG | AK8: MODERATE | AL8: 1.5 | AM8: MODERATE | AN8: 1.5 | AO8: 1.5 | AP8: 2.1 | AQ8: 7.1 | AR8: 1.5 | AS8: NA | AT8: AUTOPHAGY_HIGH | AU8: HR_DRIFT_NEGATIVE | AV8: ALTITUDE_EXTREME | AW8: ECONOMY_IMPROVING | AX8: LONG_DURATION_STRESS | AY8: MODERATE_STRAIN | AZ8: ENGINE_STABLE | BA8: Sustained high-level autophagy activation with continued negative heart rate drift and improving movement economy at extreme altitude. | BB8: 73 | BC8: 460 | BD8: 61 | BE8: 96 | BF8: 303 | BG8: 52 | BH8: 63 | BI8: 68 | BJ8: 34 | BK8: 15 | BL8: 21 | BM8: 0.4 | BN8: QUALITY_MODERATE | BO8: RECOVERY_GOOD | BP8: AUTONOMIC_STABLE | BQ8: DEPTH_HIGH | BR8: Moderate-quality sleep with extended total duration and preserved deep and REM phases. | BS8: 66 | BT8: 324 | BU8: 43 | BV8: 47 | BW8: 234 | BX8: 22 | BY8: 64 | BZ8: 70 | CA8: 29 | CB8: 17 | CC8: 25 | CD8: 0.3 | CE8: QUALITY_POOR | CF8: RECOVERY_LOW | CG8: AUTONOMIC_STRAINED | CH8: DEPTH_HIGH | CI8: Poor post-hike sleep with continued autonomic strain and suppressed HRV, but with preserved deep and REM sleep. | CJ8: 72 | CK8: 336 | CL8: 59 | CM8: 38 | CN8: 239 | CO8: 7 | CP8: 62 | CQ8: 66 | CR8: 47 | CS8: 16 | CT8: 12 | CU8: -0.2 | CV8: QUALITY_MODERATE | CW8: RECOVERY_PARTIAL | CX8: AUTONOMIC_STABLE | CY8: DEPTH_HIGH | CZ8: Moderately restorative sleep marked by stable autonomic tone and preserved deep-sleep repair. | DA8: 8.5 | DB8: 8 | DC8: 9 | DD8: 8.5 | DE8: 7 | DF8: 6.5 | DG8: 8.5 | DH8: Strong end-ketone elevation (7.1 ppm) with solid retention | DI8: Sustained high autophagy activation with no anaerobic spillover | DJ8: Continued negative HR drift (-5.6%) at extreme altitude | DK8: Extreme altitude absorbed with stable autonomic control | DL8: Partial recovery by Day 2 with elevated HRV | DM8: Mixed technical terrain with shorter duration | DN8: System variance remained tight, confirming consolidation | DO8: CONSOLIDATION | DP8: 6.9 | DQ8: 1102 | DR8: 44353 | DS8: 2.58
A9: 6 | B9: 46018 | C9: Skinsuit to Pleasant's Peak | D9: HIGH | E9: 52 | F9: 69 | G9: ='Hikes - High'!M6 -> 145 | H9: Shorts and Base layer T entire hike. | I9: None | J9: YES | K9: 10.1 | L9: 3474 | M9: 3484 | N9: 264 | O9: 0.47916667 | P9: 0.6625 | Q9: 128 | R9: 157 | S9: -0.0159 | T9: 4 | U9: 0 | V9: 139 | W9: 1070 | X9: 3893 | Y9: 46 | Z9: 50 to 52 | AA9: 54 | AB9: 88 | AC9: 67 | AD9: Rocky, Technical, Max_Exposure | AE9: Wet, Clay | AF9: CHAPARRAL | AG9: Steep, Technical | AH9: MIXED_TRAIL | AI9: 55F to 65F | AJ9: LIGHT | AK9: LIGHT | AL9: 2 | AM9: MODERATE | AN9: 1.9 | AO9: 1.9 | AP9: 2 | AQ9: 2.2 | AR9: 1.3 | AS9: NA | AT9: AUTOPHAGY_LOW | AU9: HR_DRIFT_NEGATIVE | AV9: ALTITUDE_MODERATE | AW9: ECONOMY_STABLE | AX9: PRIMED_FOR_REPAIR | AY9: LOW_STRAIN | AZ9: ENGINE_STABLE | BA9: Repair-biased fasted aerobic session with strong engine stability, negative HR drift, moderate stabilizer load from wet terrain, and shallow autophagy signaling. | BB9: 73 | BC9: 382 | BD9: 85 | BE9: 34 | BF9: 263 | BG9: 15 | BH9: 57 | BI9: 63 | BJ9: 38 | BK9: 16 | BL9: 15 | BM9: -0.5 | BN9: QUALITY_HIGH | BO9: RECOVERY_HIGH | BP9: AUTONOMIC_STABLE | BQ9: DEPTH_HIGH | BR9: High-quality sleep with strong recovery markers and stable autonomic tone. | BS9: 55 | BT9: 326 | BU9: 100 | BV9: 38 | BW9: 188 | BX9: 60 | BY9: 64 | BZ9: 70 | CA9: 30 | CB9: 19 | CC9: 30 | CD9: -0.9 | CE9: QUALITY_POOR | CF9: RECOVERY_LOW | CG9: AUTONOMIC_STRAINED | CH9: DEPTH_HIGH | CI9: Poor overall sleep with low recovery and strained autonomic tone, but strong deep sleep indicating active overnight repair. | CJ9: 75 | CK9: 333 | CL9: 43 | CM9: 51 | CN9: 239 | CO9: 17 | CP9: 58 | CQ9: 63 | CR9: 46 | CS9: 15 | CT9: 10 | CU9: 0.2 | CV9: QUALITY_HIGH | CW9: RECOVERY_GOOD | CX9: AUTONOMIC_STABLE | CY9: DEPTH_HIGH | CZ9: Restorative Day-2 sleep with stable autonomic tone, reduced overnight stress. | DA9: 6.5 | DB9: 6 | DC9: 8 | DD9: 5.5 | DE9: 4 | DF9: 6.5 | DG9: 9 | DH9: Moderate ketone rise with early plateau and limited retention | DI9: Shorter duration and lower altitude limited depth | DJ9: Negative HR drift (-3.20%) with controlled average HR | DK9: Moderate elevation produced minimal hypoxic stress | DL9: Low. Post-hike sleep strain resolved by Day-2 | DM9: Wet clay surface increased stabilizer demand | DN9: Highly stable. Tight coupling across all systems | DO9: REPAIR_BIAS | DP9: 7 | DQ9: 905 | DR9: 44233 | DS9: 2.64
A10: 7 | B10: 46039 | C10: Ski Hut to Mount Baldy, out and back | D10: HIGH | E10: 52 | F10: 69 | G10: ='Hikes - High'!N6 -> 146 | H10: Shorts and Base layer T entire hike. | I10: Micro Spikes from Tree Line to Summit | J10: YES | K10: 8.76 | L10: 4078 | M10: 4088 | N10: 345 | O10: 0.35416667 | P10: 0.59375 | Q10: 128 | R10: 155 | S10: -0.0105 | T10: 3.2 | U10: 0 | V10: 81 | W10: 6123 | X10: 10078 | Y10: 46 | Z10: 50 to 52 | AA10: 63 | AB10: 82 | AC10: 72 | AD10: Rocky, Technical, Partially Exposed | AE10: Snow, Icy | AF10: ALPINE | AG10: Steep, Extremely Technical from Post Flooding | AH10: MIXED_TRAIL | AI10: 45F to 55F | AJ10: MODERATE | AK10: STRONG | AL10: 1.5 | AM10: HIGH | AN10: 1.7 | AO10: 1.7 | AP10: 2.3 | AQ10: 6.2 | AR10: 1.5 | AS10: 1.6 | AT10: AUTOPHAGY_HIGH | AU10: HR_DRIFT_NEGATIVE | AV10: ALTITUDE_EXTREME | AW10: ECONOMY_IMPROVING | AX10: LONG_DURATION_STRESS | AY10: MODERATE_STRAIN | AZ10: ENGINE_STABLE | BA10: Fasted cold-weather alpine effort with negative HR drift, efficient fat oxidation, and a stable engine under highly technical, icy terrain. | BB10: 76 | BC10: 335 | BD10: 77 | BE10: 85 | BF10: 233 | BG10: 34 | BH10: 57 | BI10: 63 | BJ10: 41 | BK10: 16 | BL10: 14 | BM10: 0.3 | BN10: QUALITY_MODERATE | BO10: RECOVERY_GOOD | BP10: AUTONOMIC_STABLE | BQ10: DEPTH_HIGH | BR10: Short-duration but high-efficiency sleep with preserved deep and REM phases. | BS10: 50 | BT10: 359 | BU10: 118 | BV10: 15 | BW10: 226 | BX10: 55 | BY10: 63 | BZ10: 69 | CA10: 25 | CB10: 18 | CC10: 25 | CD10: -0.5 | CE10: QUALITY_POOR | CF10: RECOVERY_LOW | CG10: AUTONOMIC_STRAINED | CH10: DEPTH_HIGH | CI10: Poor post-hike sleep with continued autonomic strain and suppressed HRV, despite preserved deep sleep. | CJ10: 39 | CK10: 291 | CL10: 28 | CM10: 0 | CN10: 263 | CO10: 81 | CP10: 63 | CQ10: 65 | CR10: 43 | CS10: 12 | CT10: 14 | CU10: 0.8 | CV10: QUALITY_LOW | CW10: RECOVERY_PARTIAL | CX10: AUTONOMIC_STABLE | CY10: DEPTH_LOW | CZ10: Highly fragmented short sleep with absent REM and elevated overnight temperature. | DA10: 8.5 | DB10: 8 | DC10: 9 | DD10: 8.5 | DE10: 7 | DF10: 6.5 | DG10: 8.5 | DH10: Strong end-ketone elevation (6.2 ppm) with efficient switching | DI10: Sustained autophagy activation; depth reduced by shorter exposure | DJ10: Continued negative HR drift (-4.9%) under extreme conditions | DK10: Extreme altitude stress absorbed with reduced physiological cost | DL10: Partial recovery by Day 2, bounded and non-accumulative | DM10: Highly technical, icy terrain increased neuromuscular demand | DN10: System variance remained tight, confirming consolidation | DO10: CONSOLIDATION | DP10: 6.3 | DQ10: 343 | DR10: 24076 | DS10: 2.13
A11: 8 | B11: 46047 | C11: Ski Hut to Mount Baldy, out and back | D11: HIGH | E11: 52 | F11: 69 | G11: ='Hikes - High'!O6 -> 146 | H11: Wind shell till Baldy Saddle. Then, Shorts and Base layer T rest of hike. | I11: Micro Spikes from Tree Line to Summit | J11: NO | K11: 8.3 | L11: 3996 | M11: 4242 | N11: 341 | O11: 0.39583333 | P11: 0.63263889 | Q11: 128 | R11: 151 | S11: -0.0002 | T11: 3.3 | U11: 0.1 | V11: 85 | W11: 5909 | X11: 10072 | Y11: 46 | Z11: 50 to 52 | AA11: 50 | AB11: 75 | AC11: 59 | AD11: Rocky, Technical, Partially Exposed | AE11: Snow, Icy | AF11: ALPINE | AG11: Steep, Extremely Technical from Post Flooding | AH11: MIXED_TRAIL | AI11: 40F to 50F | AJ11: MODERATE | AK11: STRONG | AL11: 2 | AM11: MODERATE | AN11: 2.1 | AO11: 2.1 | AP11: 2.6 | AQ11: 8.4 | AR11: 1.9 | AS11: NA | AT11: AUTOPHAGY_HIGH | AU11: HR_DRIFT_NEGATIVE | AV11: ALTITUDE_EXTREME | AW11: ECONOMY_IMPROVING | AX11: LONG_DURATION_STRESS | AY11: MODERATE_STRAIN | AZ11: ENGINE_STABLE | BA11: Fasted cold-weather alpine effort with sustained negative heart rate drift, efficient fat oxidation, and a stable engine under highly technical, icy terrain. | BB11: 91 | BC11: 441 | BD11: 104 | BE11: 90 | BF11: 248 | BG11: 10 | BH11: 61 | BI11: 66 | BJ11: 41 | BK11: 15 | BL11: 12 | BM11: 0.6 | BN11: QUALITY_HIGH | BO11: RECOVERY_GOOD | BP11: AUTONOMIC_STABLE | BQ11: DEPTH_HIGH | BR11: High-quality restorative sleep with extended deep and REM duration, low awakenings. | BS11: 62 | BT11: 405 | BU11: 92 | BV11: 52 | BW11: 261 | BX11: 64 | BY11: 61 | BZ11: 69 | CA11: 29 | CB11: 16 | CC11: 23 | CD11: 0.3 | CE11: QUALITY_POOR | CF11: RECOVERY_LOW | CG11: AUTONOMIC_STRAINED | CH11: DEPTH_HIGH | CI11: Poor post-hike sleep with continued autonomic strain and suppressed HRV, despite improved REM duration. | CJ11: 71 | CK11: 334 | CL11: 60 | CM11: 62 | CN11: 212 | CO11: 26 | CP11: 60 | CQ11: 67 | CR11: 40 | CS11: 16 | CT11: 15 | CU11: -0.6 | CV11: QUALITY_MODERATE | CW11: RECOVERY_PARTIAL | CX11: AUTONOMIC_STABLE | CY11: DEPTH_HIGH | CZ11: Moderately restorative sleep with stable autonomic tone and preserved deep-sleep repair. | DA11: 8.5 | DB11: 8 | DC11: 9 | DD11: 8.5 | DE11: 7 | DF11: 6.5 | DG11: 8.5 | DH11: Strong end-ketone elevation (8.4 ppm) with good retention | DI11: Sustained autophagy; depth modestly capped by duration | DJ11: Continued negative HR drift (-5.2%) under technical terrain | DK11: Extreme altitude absorbed with consistent cardiovascular efficiency | DL11: Recovery debt present but stable and non-accumulative | DM11: Highly technical, icy terrain with refined movement efficiency | DN11: System variance tight despite cold exposure and technical terrain | DO11: CONSOLIDATION | DP11: 6.2 | DQ11: 166 | DR11: 20150 | DS11: 2.45
A12: 9 | B12: 46053 | C12: Ski Hut to Mount Baldy, out and back | D12: HIGH | E12: 52 | F12: 69 | G12: ='Hikes - High'!P6 -> 146 | H12: Shorts and Base Layer T shirt entire hike. | I12: None | J12: NO | K12: 8.65 | L12: 4042 | M12: 4035 | N12: 324 | O12: 0.375 | P12: 0.6 | Q12: 128 | R12: 150 | S12: -0.0152 | T12: 3.2 | U12: 0 | V12: 76 | W12: 6129 | X12: 10111 | Y12: 46 | Z12: 50 to 52 | AA12: 61 | AB12: 84 | AC12: 71 | AD12: Rocky, Technical, Partially Exposed | AE12: Snow, Icy and Slippery | AF12: ALPINE | AG12: Steep, Extremely Technical from Post Flooding | AH12: MIXED_TRAIL | AI12: 50F to 65F | AJ12: CALM | AK12: STRONG | AL12: 2 | AM12: MODERATE | AN12: 2.2 | AO12: 2.2 | AP12: 1.9 | AQ12: 6.8 | AR12: 1.8 | AS12: 2.1 | AT12: AUTOPHAGY_HIGH | AU12: HR_DRIFT_NEGATIVE | AV12: ALTITUDE_EXTREME | AW12: ECONOMY_IMPROVING | AX12: LONG_DURATION_STRESS | AY12: MODERATE_STRAIN | AZ12: ENGINE_STABLE | BA12: Fasted cold-weather alpine effort with sustained negative heart rate drift, efficient fat oxidation, and a stable engine under icy, highly technical terrain. | BB12: 52 | BC12: 419 | BD12: 64 | BE12: 75 | BF12: 261 | BG12: 102 | BH12: 61 | BI12: 66 | BJ12: 37 | BK12: 16 | BL12: 16 | BM12: 0.1 | BN12: QUALITY_LOW | BO12: RECOVERY_PARTIAL | BP12: AUTONOMIC_STABLE | BQ12: DEPTH_MODERATE | BR12: Fragmented short sleep with very high awakenings, reduced total duration. | BS12: 56 | BT12: 369 | BU12: 72 | BV12: 5 | BW12: 292 | BX12: 38 | BY12: 62 | BZ12: 67 | CA12: 32 | CB12: 17 | CC12: 22 | CD12: -0.6 | CE12: QUALITY_POOR | CF12: RECOVERY_LOW | CG12: AUTONOMIC_STRAINED | CH12: DEPTH_HIGH | CI12: Poor post-hike sleep with continued autonomic strain and suppressed HRV, despite preserved deep sleep. | CJ12: 59 | CK12: 371 | CL12: 64 | CM12: 23 | CN12: 254 | CO12: 29 | CP12: 63 | CQ12: 68 | CR12: 31 | CS12: 16 | CT12: 22 | CU12: 0.1 | CV12: QUALITY_MODERATE | CW12: RECOVERY_PARTIAL | CX12: AUTONOMIC_STABLE | CY12: DEPTH_HIGH | CZ12: Moderately restorative sleep with stable autonomic tone and preserved deep-sleep repair. | DA12: 8.5 | DB12: 8 | DC12: 9 | DD12: 8.5 | DE12: 7 | DF12: 6.5 | DG12: 8.5 | DH12: Strong end-ketone elevation (6.8 ppm) with solid retention | DI12: Sustained autophagy within high-adaptation zone | DJ12: Continued negative HR drift (-5.0%) under icy terrain | DK12: Extreme altitude absorbed with stable autonomic control | DL12: Recovery debt remains present but stable | DM12: Icy terrain increased demand but efficiency constrained stress | DN12: System variance tight, confirming stable engine behavior | DO12: CONSOLIDATION | DP12: 5.8 | DQ12: 242 | DR12: 30261 | DS12: 2.27
A13: 10 | B13: 46060 | C13: Ski Hut to Mount Baldy, out and back | D13: HIGH | E13: 52 | F13: 69 | G13: ='Hikes - High'!Q6 -> 146 | H13: Shorts and Base Layer T shirt half of hike. Wind Shell the rest. | I13: None | J13: NO | K13: 8.83 | L13: 4121 | M13: 4117 | N13: 327 | O13: 0.35416667 | P13: 0.58125 | Q13: 128 | R13: 150 | S13: -0.017 | T13: 3 | U13: 0 | V13: 63 | W13: 6114 | X13: 10089 | Y13: 46 | Z13: 50 to 52 | AA13: 45 | AB13: 77 | AC13: 60 | AD13: Rocky, Technical, Partially Exposed | AE13: Partial Snow | AF13: ALPINE | AG13: Steep, Extremely Technical | AH13: MIXED_TRAIL | AI13: 45F to 55F | AJ13: STRONG | AK13: MODERATE | AL13: 2 | AM13: MODERATE | AN13: 2.2 | AO13: 2.2 | AP13: NA | AQ13: 7.8 | AR13: 2.1 | AS13: 2.1 | AT13: AUTOPHAGY_HIGH | AU13: HR_DRIFT_NEGATIVE | AV13: ALTITUDE_EXTREME | AW13: ECONOMY_IMPROVING | AX13: LONG_DURATION_STRESS | AY13: MODERATE_STRAIN | AZ13: ENGINE_STABLE | BA13: Fasted cold-weather alpine effort with sustained negative heart rate drift, efficient fat oxidation, and a stable engine under mixed snow and highly technical terrain. | BB13: 78 | BC13: 358 | BD13: 72 | BE13: 67 | BF13: 219 | BG13: 6 | BH13: 57 | BI13: 62 | BJ13: 36 | BK13: 15 | BL13: 12 | BM13: -0.2 | BN13: QUALITY_MODERATE | BO13: RECOVERY_GOOD | BP13: AUTONOMIC_STABLE | BQ13: DEPTH_MODERATE | BR13: Moderate-quality, shortened sleep with preserved deep and REM phases. | BS13: 71 | BT13: 308 | BU13: 89 | BV13: 63 | BW13: 216 | BX13: 29 | BY13: 63 | BZ13: 67 | CA13: 23 | CB13: 17 | CC13: 24 | CD13: -0.1 | CE13: QUALITY_POOR | CF13: RECOVERY_LOW | CG13: AUTONOMIC_STRAINED | CH13: DEPTH_HIGH | CI13: Poor post-hike sleep marked by continued autonomic strain and suppressed HRV, despite preserved deep and REM sleep. | CJ13: 65 | CK13: 412 | CL13: 92 | CM13: 84 | CN13: 236 | CO13: 59 | CP13: 61 | CQ13: 66 | CR13: 39 | CS13: 15 | CT13: 16 | CU13: 0.3 | CV13: QUALITY_MODERATE | CW13: RECOVERY_PARTIAL | CX13: AUTONOMIC_STABLE | CY13: DEPTH_HIGH | CZ13: Moderately restorative sleep with stable autonomic tone and strong deep-sleep repair. | DA13: 8.5 | DB13: 8 | DC13: 9 | DD13: 8.5 | DE13: 7 | DF13: 6.5 | DG13: 8.5 | DH13: Strong end-ketone elevation with solid retention | DI13: Sustained autophagy within high-adaptation zone | DJ13: Continued negative HR drift (-5.1%) under technical terrain | DK13: Extreme altitude absorbed, reinforcing consolidated adaptation | DL13: Recovery debt remains present but stable | DM13: Highly technical terrain with refined movement efficiency | DN13: System variance tight, confirming stable engine behavior | DO13: CONSOLIDATION | DP13: 6.4 | DQ13: 305 | DR13: 40350 | DS13: 2.27
A14: 11 | B14: 46068 | C14: Sturtevant Falls to Mount Wilson | D14: HIGH | E14: 52 | F14: 69 | G14: ='Hikes - High'!R6 -> 146 | H14: Shorts and windshell 75% of hike. Shorts and T 25% remainder. | I14: None | J14: NO | K14: 15 | L14: 4770 | M14: 4738 | N14: 339 | O14: 0.27083333 | P14: 0.50625 | Q14: 128 | R14: 165 | S14: -0.0092 | T14: 3.7 | U14: 0.1 | V14: 121 | W14: 1806 | X14: 5762 | Y14: 46 | Z14: 50 to 52 | AA14: 54 | AB14: 77 | AC14: 60 | AD14: Rocky, Alpine, River Crossings, exposed switchbacks | AE14: Rocky, Slippery, Mixed | AF14: ALPINE | AG14: Steep, Technical | AH14: MIXED_TRAIL | AI14: 45F to 55F | AJ14: STRONG | AK14: CLOUDY | AL14: 2 | AM14: MODERATE | AN14: 2.1 | AO14: 2.1 | AP14: NA | AQ14: 11 | AR14: 2.4 | AS14: 2.2 | AT14: AUTOPHAGY_DEEP | AU14: HR_DRIFT_NEGATIVE | AV14: ALTITUDE_MODERATE | AW14: ECONOMY_IMPROVING | AX14: LONG_DURATION_STRESS | AY14: MODERATE_STRAIN | AZ14: ENGINE_STABLE | BA14: Fasted long-distance alpine effort on a novel trail with controlled average heart rate, high max HR spike, and strong end-ketone elevation (11 ppm) matching peak autophagy sessions. Extended distance (15 mi) and elevation gain (4,770 ft) at moderate altitude produced deep substrate switching without anaerobic spillover. Rocky, slippery mixed terrain with river crossings and exposed switchbacks increased neuromuscular demand. Despite very short pre-hike sleep, cardiovascular control remained effective and the engine pattern held stable, reflecting durable efficiency and metabolic depth under novel, prolonged stress. | BB14: 57 | BC14: 254 | BD14: 70 | BE14: 48 | BF14: 136 | BG14: 5 | BH14: 57 | BI14: 62 | BJ14: 36 | BK14: 15 | BL14: 14 | BM14: 0.2 | BN14: QUALITY_LOW | BO14: RECOVERY_PARTIAL | BP14: AUTONOMIC_STABLE | BQ14: DEPTH_MODERATE | BR14: Very short pre-hike sleep with extremely low total duration (254 min), likely truncated by the early start time required for the 15-mile Mount Wilson effort. Despite minimal sleep volume, deep and REM phases were preserved in proportion, resting heart rate remained low (57 bpm), and autonomic tone stayed stable with moderate HRV (36). Pattern indicates severely compressed recovery window entering the hike, with partial readiness sustained by low baseline stress markers and stable overnight physiology. | BS14: 54 | BT14: 227 | BU14: 118 | BV14: 25 | BW14: 184 | BX14: 50 | BY14: 65 | BZ14: 72 | CA14: 24 | CB14: 19 | CC14: 30 | CD14: -0.5 | CE14: QUALITY_POOR | CF14: RECOVERY_LOW | CG14: AUTONOMIC_STRAINED | CH14: DEPTH_HIGH | CI14: Poor post-hike sleep with deeply suppressed HRV (24), elevated resting HR (65 bpm), and shortened total duration (227 min), but exceptionally strong deep sleep (118 min) indicating aggressive overnight tissue repair and mitochondrial recovery. REM was heavily suppressed (25 min) and awakenings elevated (50 min), reflecting continued autonomic strain from the longest and most novel effort to date. Elevated respiratory rate (19) and overnight stress (30) confirm systemic recovery demand remains high. Deep-sleep dominance signals the body prioritized structural repair over cognitive restoration on Day 1. | CJ14: 64 | CK14: 328 | CL14: 58 | CM14: 19 | CN14: 311 | CO14: 6 | CP14: 63 | CQ14: 68 | CR14: 35 | CS14: 17 | CT14: 21 | CU14: 0.7 | CV14: QUALITY_MODERATE | CW14: RECOVERY_PARTIAL | CX14: AUTONOMIC_STABLE | CY14: DEPTH_MODERATE | CZ14: Moderately restorative Day-2 sleep with stable autonomic tone and reduced resting heart rate (63 bpm), but markedly suppressed REM (19 min — lowest across all weeks) and moderate deep sleep (58 min). Total duration improved (328 min) and awakenings dropped sharply (6 min), indicating structural recovery is progressing. However, the near-absent REM combined with elevated skin temperature (+0.7°F) suggests continued inflammatory signaling and unresolved neural recalibration from the novel 15-mile effort. HRV returned to 35, matching baseline, but cognitive and hormonal restoration remains incomplete two days post-hike. | DA14: 9 | DB14: 9 | DC14: 8 | DD14: 6 | DE14: 7 | DF14: 7.5 | DG14: 8 | DH14: Very high end-ketone elevation (11 ppm) with strong next-day retention (2.4 ppm) and solid Day-2 persistence (2.2 ppm) indicates deep metabolic flexibility and efficient substrate switching under prolonged novel alpine stress, matching peak sessions despite moderate altitude. | DI14: Deep autophagy activation driven by very high end-ketone elevation (11 ppm) under the longest fasted effort to date (15 mi, 339 min). Strong next-day retention confirms sustained cellular clearance signaling despite suppressed post-hike REM and novel terrain demands. | DJ14: Controlled average heart rate (128 bpm) over the longest distance (15 mi) with the highest max HR spike (165 bpm) of any recent hike, reflecting cardiovascular reserve under novel terrain stress. HR drift estimated at -5.8%, confirming durable cardiac efficiency. | DK14: Moderate altitude exposure (peak 5,762 ft) produced manageable hypoxic load compared to Baldy's extreme altitude sessions (10,000+ ft). Physiological cost was contained with stable autonomic control, placing this effort in the moderate adaptation zone similar to Skinsuit sessions. | DL14: Significant recovery debt from the combination of compressed pre-hike sleep (254 min), the longest and most novel effort to date, and deeply suppressed post-hike HRV (24) with elevated resting HR. Day-2 HRV returned to baseline (35) but REM remained critically suppressed (19 min), indicating ongoing neural and cognitive recalibration. Debt is elevated but bounded. | DM14: Highest distance (15 mi) and elevation gain (4,770 ft) of any hike to date over rocky, slippery mixed terrain with river crossings and exposed switchbacks. Novel trail demands increased proprioceptive and neuromuscular load beyond typical Baldy sessions, elevating mechanical stress despite controlled pacing. | DN14: System variance remained contained across metabolic, cardiac, and recovery domains despite the novel trail, longest distance, and highest mechanical stress of any session. The engine absorbed a qualitatively different stress profile without instability, confirming robust adaptability beyond the established Baldy and Skinsuit patterns. | DO14: METABOLIC | DP14: 7 | DQ14: 345 | DR14: 36034 | DS14: 2.25
